2025-09-23 23:15:24,570 - epetcare - INFO - Starting ePetCare Vet Desktop Application
2025-09-23 23:15:24,611 - epetcare - ERROR - Failed to import module: models.data_access - No module named 'models.data_access'; 'models' is not a package
2025-09-23 23:15:24,611 - epetcare - WARNING - Some modules could not be imported. Trying alternative approaches...
2025-09-23 23:15:24,612 - epetcare - ERROR - Failed to manually load package models: module 'importlib' has no attribute 'util'
2025-09-23 23:15:24,613 - epetcare - ERROR - Traceback (most recent call last):
  File "C:\epetcare\vet_desktop_app\module_finder.py", line 124, in ensure_modules_importable
    module = importlib.util.module_from_spec(spec)
             ^^^^^^^^^^^^^^
AttributeError: module 'importlib' has no attribute 'util'

2025-09-23 23:15:24,614 - epetcare - ERROR - Failed to manually load models.data_access from C:\epetcare\vet_desktop_app\models\data_access.py: module 'importlib' has no attribute 'util'
2025-09-23 23:15:24,614 - epetcare - ERROR - Traceback (most recent call last):
  File "C:\epetcare\vet_desktop_app\module_finder.py", line 106, in ensure_modules_importable
    spec = importlib.util.spec_from_file_location(module_name, module_path)
           ^^^^^^^^^^^^^^
AttributeError: module 'importlib' has no attribute 'util'

2025-09-23 23:15:24,615 - epetcare - ERROR - Failed to manually load models.models from C:\epetcare\vet_desktop_app\models\models.py: module 'importlib' has no attribute 'util'
2025-09-23 23:15:24,615 - epetcare - ERROR - Traceback (most recent call last):
  File "C:\epetcare\vet_desktop_app\module_finder.py", line 106, in ensure_modules_importable
    spec = importlib.util.spec_from_file_location(module_name, module_path)
           ^^^^^^^^^^^^^^
AttributeError: module 'importlib' has no attribute 'util'

2025-09-23 23:15:24,616 - epetcare - ERROR - Failed to manually load package views: module 'importlib' has no attribute 'util'
2025-09-23 23:15:24,616 - epetcare - ERROR - Traceback (most recent call last):
  File "C:\epetcare\vet_desktop_app\module_finder.py", line 124, in ensure_modules_importable
    module = importlib.util.module_from_spec(spec)
             ^^^^^^^^^^^^^^
AttributeError: module 'importlib' has no attribute 'util'

2025-09-23 23:15:24,617 - epetcare - ERROR - Failed to manually load views.main_window from C:\epetcare\vet_desktop_app\views\main_window.py: module 'importlib' has no attribute 'util'
2025-09-23 23:15:24,618 - epetcare - ERROR - Traceback (most recent call last):
  File "C:\epetcare\vet_desktop_app\module_finder.py", line 106, in ensure_modules_importable
    spec = importlib.util.spec_from_file_location(module_name, module_path)
           ^^^^^^^^^^^^^^
AttributeError: module 'importlib' has no attribute 'util'

2025-09-23 23:15:24,618 - epetcare - ERROR - Failed to manually load views.login_dialog from C:\epetcare\vet_desktop_app\views\login_dialog.py: module 'importlib' has no attribute 'util'
2025-09-23 23:15:24,619 - epetcare - ERROR - Traceback (most recent call last):
  File "C:\epetcare\vet_desktop_app\module_finder.py", line 106, in ensure_modules_importable
    spec = importlib.util.spec_from_file_location(module_name, module_path)
           ^^^^^^^^^^^^^^
AttributeError: module 'importlib' has no attribute 'util'

2025-09-23 23:15:24,619 - epetcare - ERROR - Failed to manually load views.register_dialog from C:\epetcare\vet_desktop_app\views\register_dialog.py: module 'importlib' has no attribute 'util'
2025-09-23 23:15:24,620 - epetcare - ERROR - Traceback (most recent call last):
  File "C:\epetcare\vet_desktop_app\module_finder.py", line 106, in ensure_modules_importable
    spec = importlib.util.spec_from_file_location(module_name, module_path)
           ^^^^^^^^^^^^^^
AttributeError: module 'importlib' has no attribute 'util'

2025-09-23 23:15:24,620 - epetcare - ERROR - Failed to manually load package utils: module 'importlib' has no attribute 'util'
2025-09-23 23:15:24,620 - epetcare - ERROR - Traceback (most recent call last):
  File "C:\epetcare\vet_desktop_app\module_finder.py", line 124, in ensure_modules_importable
    module = importlib.util.module_from_spec(spec)
             ^^^^^^^^^^^^^^
AttributeError: module 'importlib' has no attribute 'util'

2025-09-23 23:15:24,621 - epetcare - ERROR - Failed to manually load utils.database from C:\epetcare\vet_desktop_app\utils\database.py: module 'importlib' has no attribute 'util'
2025-09-23 23:15:24,621 - epetcare - ERROR - Traceback (most recent call last):
  File "C:\epetcare\vet_desktop_app\module_finder.py", line 106, in ensure_modules_importable
    spec = importlib.util.spec_from_file_location(module_name, module_path)
           ^^^^^^^^^^^^^^
AttributeError: module 'importlib' has no attribute 'util'

2025-09-23 23:15:24,622 - epetcare - ERROR - Failed to manually load utils.config from C:\epetcare\vet_desktop_app\utils\config.py: module 'importlib' has no attribute 'util'
2025-09-23 23:15:24,622 - epetcare - ERROR - Traceback (most recent call last):
  File "C:\epetcare\vet_desktop_app\module_finder.py", line 106, in ensure_modules_importable
    spec = importlib.util.spec_from_file_location(module_name, module_path)
           ^^^^^^^^^^^^^^
AttributeError: module 'importlib' has no attribute 'util'

2025-09-23 23:15:24,623 - epetcare - ERROR - Failed to manually load utils.notification_manager from C:\epetcare\vet_desktop_app\utils\notification_manager.py: module 'importlib' has no attribute 'util'
2025-09-23 23:15:24,623 - epetcare - ERROR - Traceback (most recent call last):
  File "C:\epetcare\vet_desktop_app\module_finder.py", line 106, in ensure_modules_importable
    spec = importlib.util.spec_from_file_location(module_name, module_path)
           ^^^^^^^^^^^^^^
AttributeError: module 'importlib' has no attribute 'util'

2025-09-23 23:15:24,624 - epetcare - WARNING - Some modules still missing: ['models.data_access', 'models.models', 'views', 'views.main_window', 'views.login_dialog', 'views.register_dialog', 'utils', 'utils.database', 'utils.config', 'utils.notification_manager']
2025-09-23 23:15:24,963 - epetcare - ERROR - Error importing view modules: No module named 'models.data_access'; 'models' is not a package
2025-09-23 23:15:24,965 - epetcare - ERROR - Traceback (most recent call last):
  File "C:\epetcare\vet_desktop_app\views\__init__.py", line 132, in <module>
    from . import main_window
  File "C:\epetcare\vet_desktop_app\views\main_window.py", line 118, in <module>
    from views.login_dialog import LoginDialog
  File "C:\epetcare\vet_desktop_app\views\login_dialog.py", line 93, in <module>
    from models.data_access import UserDataAccess, VeterinarianDataAccess
ModuleNotFoundError: No module named 'models.data_access'; 'models' is not a package

2025-09-23 23:15:24,995 - epetcare - ERROR - Failed to import application modules: No module named 'models.data_access'; 'models' is not a package
2025-09-23 23:15:25,038 - epetcare - ERROR - Traceback (most recent call last):
  File "C:\epetcare\vet_desktop_app\main.py", line 78, in <module>
    from views.main_window import MainWindow
  File "C:\epetcare\vet_desktop_app\views\main_window.py", line 118, in <module>
    from views.login_dialog import LoginDialog
  File "C:\epetcare\vet_desktop_app\views\login_dialog.py", line 93, in <module>
    from models.data_access import UserDataAccess, VeterinarianDataAccess
ModuleNotFoundError: No module named 'models.data_access'; 'models' is not a package

2025-09-23 23:15:25,039 - epetcare - ERROR - Error during startup: No module named 'models.data_access'; 'models' is not a package
2025-09-23 23:15:25,041 - epetcare - ERROR - Traceback (most recent call last):
  File "C:\epetcare\vet_desktop_app\main.py", line 78, in <module>
    from views.main_window import MainWindow
  File "C:\epetcare\vet_desktop_app\views\main_window.py", line 118, in <module>
    from views.login_dialog import LoginDialog
  File "C:\epetcare\vet_desktop_app\views\login_dialog.py", line 93, in <module>
    from models.data_access import UserDataAccess, VeterinarianDataAccess
ModuleNotFoundError: No module named 'models.data_access'; 'models' is not a package

2025-09-23 23:20:37,169 - epetcare - INFO - Starting ePetCare Vet Desktop Application
2025-09-23 23:20:37,207 - epetcare - ERROR - Failed to import module: models.data_access - No module named 'models.data_access'; 'models' is not a package
2025-09-23 23:20:37,207 - epetcare - WARNING - Some modules could not be imported. Trying alternative approaches...
2025-09-23 23:20:37,208 - epetcare - ERROR - Failed to manually load package models: module 'importlib' has no attribute 'util'
2025-09-23 23:20:37,208 - epetcare - ERROR - Traceback (most recent call last):
  File "C:\epetcare\vet_desktop_app\module_finder.py", line 124, in ensure_modules_importable
    module = importlib.util.module_from_spec(spec)
             ^^^^^^^^^^^^^^
AttributeError: module 'importlib' has no attribute 'util'

2025-09-23 23:20:37,209 - epetcare - ERROR - Failed to manually load models.data_access from C:\epetcare\vet_desktop_app\models\data_access.py: module 'importlib' has no attribute 'util'
2025-09-23 23:20:37,209 - epetcare - ERROR - Traceback (most recent call last):
  File "C:\epetcare\vet_desktop_app\module_finder.py", line 106, in ensure_modules_importable
    spec = importlib.util.spec_from_file_location(module_name, module_path)
           ^^^^^^^^^^^^^^
AttributeError: module 'importlib' has no attribute 'util'

2025-09-23 23:20:37,210 - epetcare - ERROR - Failed to manually load models.models from C:\epetcare\vet_desktop_app\models\models.py: module 'importlib' has no attribute 'util'
2025-09-23 23:20:37,210 - epetcare - ERROR - Traceback (most recent call last):
  File "C:\epetcare\vet_desktop_app\module_finder.py", line 106, in ensure_modules_importable
    spec = importlib.util.spec_from_file_location(module_name, module_path)
           ^^^^^^^^^^^^^^
AttributeError: module 'importlib' has no attribute 'util'

2025-09-23 23:20:37,211 - epetcare - ERROR - Failed to manually load package views: module 'importlib' has no attribute 'util'
2025-09-23 23:20:37,212 - epetcare - ERROR - Traceback (most recent call last):
  File "C:\epetcare\vet_desktop_app\module_finder.py", line 124, in ensure_modules_importable
    module = importlib.util.module_from_spec(spec)
             ^^^^^^^^^^^^^^
AttributeError: module 'importlib' has no attribute 'util'

2025-09-23 23:20:37,212 - epetcare - ERROR - Failed to manually load views.main_window from C:\epetcare\vet_desktop_app\views\main_window.py: module 'importlib' has no attribute 'util'
2025-09-23 23:20:37,213 - epetcare - ERROR - Traceback (most recent call last):
  File "C:\epetcare\vet_desktop_app\module_finder.py", line 106, in ensure_modules_importable
    spec = importlib.util.spec_from_file_location(module_name, module_path)
           ^^^^^^^^^^^^^^
AttributeError: module 'importlib' has no attribute 'util'

2025-09-23 23:20:37,213 - epetcare - ERROR - Failed to manually load views.login_dialog from C:\epetcare\vet_desktop_app\views\login_dialog.py: module 'importlib' has no attribute 'util'
2025-09-23 23:20:37,214 - epetcare - ERROR - Traceback (most recent call last):
  File "C:\epetcare\vet_desktop_app\module_finder.py", line 106, in ensure_modules_importable
    spec = importlib.util.spec_from_file_location(module_name, module_path)
           ^^^^^^^^^^^^^^
AttributeError: module 'importlib' has no attribute 'util'

2025-09-23 23:20:37,215 - epetcare - ERROR - Failed to manually load views.register_dialog from C:\epetcare\vet_desktop_app\views\register_dialog.py: module 'importlib' has no attribute 'util'
2025-09-23 23:20:37,216 - epetcare - ERROR - Traceback (most recent call last):
  File "C:\epetcare\vet_desktop_app\module_finder.py", line 106, in ensure_modules_importable
    spec = importlib.util.spec_from_file_location(module_name, module_path)
           ^^^^^^^^^^^^^^
AttributeError: module 'importlib' has no attribute 'util'

2025-09-23 23:20:37,216 - epetcare - ERROR - Failed to manually load package utils: module 'importlib' has no attribute 'util'
2025-09-23 23:20:37,217 - epetcare - ERROR - Traceback (most recent call last):
  File "C:\epetcare\vet_desktop_app\module_finder.py", line 124, in ensure_modules_importable
    module = importlib.util.module_from_spec(spec)
             ^^^^^^^^^^^^^^
AttributeError: module 'importlib' has no attribute 'util'

2025-09-23 23:20:37,218 - epetcare - ERROR - Failed to manually load utils.database from C:\epetcare\vet_desktop_app\utils\database.py: module 'importlib' has no attribute 'util'
2025-09-23 23:20:37,219 - epetcare - ERROR - Traceback (most recent call last):
  File "C:\epetcare\vet_desktop_app\module_finder.py", line 106, in ensure_modules_importable
    spec = importlib.util.spec_from_file_location(module_name, module_path)
           ^^^^^^^^^^^^^^
AttributeError: module 'importlib' has no attribute 'util'

2025-09-23 23:20:37,219 - epetcare - ERROR - Failed to manually load utils.config from C:\epetcare\vet_desktop_app\utils\config.py: module 'importlib' has no attribute 'util'
2025-09-23 23:20:37,220 - epetcare - ERROR - Traceback (most recent call last):
  File "C:\epetcare\vet_desktop_app\module_finder.py", line 106, in ensure_modules_importable
    spec = importlib.util.spec_from_file_location(module_name, module_path)
           ^^^^^^^^^^^^^^
AttributeError: module 'importlib' has no attribute 'util'

2025-09-23 23:20:37,222 - epetcare - ERROR - Failed to manually load utils.notification_manager from C:\epetcare\vet_desktop_app\utils\notification_manager.py: module 'importlib' has no attribute 'util'
2025-09-23 23:20:37,223 - epetcare - ERROR - Traceback (most recent call last):
  File "C:\epetcare\vet_desktop_app\module_finder.py", line 106, in ensure_modules_importable
    spec = importlib.util.spec_from_file_location(module_name, module_path)
           ^^^^^^^^^^^^^^
AttributeError: module 'importlib' has no attribute 'util'

2025-09-23 23:20:37,223 - epetcare - WARNING - Some modules still missing: ['models.data_access', 'models.models', 'views', 'views.main_window', 'views.login_dialog', 'views.register_dialog', 'utils', 'utils.database', 'utils.config', 'utils.notification_manager']
2025-09-23 23:20:37,380 - epetcare - ERROR - Error importing view modules: No module named 'models.data_access'; 'models' is not a package
2025-09-23 23:20:37,382 - epetcare - ERROR - Traceback (most recent call last):
  File "C:\epetcare\vet_desktop_app\views\__init__.py", line 132, in <module>
    from . import main_window
  File "C:\epetcare\vet_desktop_app\views\main_window.py", line 118, in <module>
    from views.login_dialog import LoginDialog
  File "C:\epetcare\vet_desktop_app\views\login_dialog.py", line 93, in <module>
    from models.data_access import UserDataAccess, VeterinarianDataAccess
ModuleNotFoundError: No module named 'models.data_access'; 'models' is not a package

2025-09-23 23:20:37,395 - epetcare - ERROR - Failed to import application modules: No module named 'models.data_access'; 'models' is not a package
2025-09-23 23:20:37,399 - epetcare - ERROR - Traceback (most recent call last):
  File "C:\epetcare\vet_desktop_app\main.py", line 78, in <module>
    from views.main_window import MainWindow
  File "C:\epetcare\vet_desktop_app\views\main_window.py", line 118, in <module>
    from views.login_dialog import LoginDialog
  File "C:\epetcare\vet_desktop_app\views\login_dialog.py", line 93, in <module>
    from models.data_access import UserDataAccess, VeterinarianDataAccess
ModuleNotFoundError: No module named 'models.data_access'; 'models' is not a package

2025-09-23 23:20:37,399 - epetcare - ERROR - Error during startup: No module named 'models.data_access'; 'models' is not a package
2025-09-23 23:20:37,402 - epetcare - ERROR - Traceback (most recent call last):
  File "C:\epetcare\vet_desktop_app\main.py", line 78, in <module>
    from views.main_window import MainWindow
  File "C:\epetcare\vet_desktop_app\views\main_window.py", line 118, in <module>
    from views.login_dialog import LoginDialog
  File "C:\epetcare\vet_desktop_app\views\login_dialog.py", line 93, in <module>
    from models.data_access import UserDataAccess, VeterinarianDataAccess
ModuleNotFoundError: No module named 'models.data_access'; 'models' is not a package

2025-09-23 23:20:40,427 - epetcare - INFO - Starting ePetCare Vet Desktop Application
2025-09-23 23:20:40,460 - epetcare - ERROR - Failed to import module: models.data_access - No module named 'models.data_access'; 'models' is not a package
2025-09-23 23:20:40,460 - epetcare - WARNING - Some modules could not be imported. Trying alternative approaches...
2025-09-23 23:20:40,461 - epetcare - ERROR - Failed to manually load package models: module 'importlib' has no attribute 'util'
2025-09-23 23:20:40,462 - epetcare - ERROR - Traceback (most recent call last):
  File "C:\epetcare\vet_desktop_app\module_finder.py", line 124, in ensure_modules_importable
    module = importlib.util.module_from_spec(spec)
             ^^^^^^^^^^^^^^
AttributeError: module 'importlib' has no attribute 'util'

2025-09-23 23:20:40,462 - epetcare - ERROR - Failed to manually load models.data_access from C:\epetcare\vet_desktop_app\models\data_access.py: module 'importlib' has no attribute 'util'
2025-09-23 23:20:40,463 - epetcare - ERROR - Traceback (most recent call last):
  File "C:\epetcare\vet_desktop_app\module_finder.py", line 106, in ensure_modules_importable
    spec = importlib.util.spec_from_file_location(module_name, module_path)
           ^^^^^^^^^^^^^^
AttributeError: module 'importlib' has no attribute 'util'

2025-09-23 23:20:40,463 - epetcare - ERROR - Failed to manually load models.models from C:\epetcare\vet_desktop_app\models\models.py: module 'importlib' has no attribute 'util'
2025-09-23 23:20:40,463 - epetcare - ERROR - Traceback (most recent call last):
  File "C:\epetcare\vet_desktop_app\module_finder.py", line 106, in ensure_modules_importable
    spec = importlib.util.spec_from_file_location(module_name, module_path)
           ^^^^^^^^^^^^^^
AttributeError: module 'importlib' has no attribute 'util'

2025-09-23 23:20:40,464 - epetcare - ERROR - Failed to manually load package views: module 'importlib' has no attribute 'util'
2025-09-23 23:20:40,465 - epetcare - ERROR - Traceback (most recent call last):
  File "C:\epetcare\vet_desktop_app\module_finder.py", line 124, in ensure_modules_importable
    module = importlib.util.module_from_spec(spec)
             ^^^^^^^^^^^^^^
AttributeError: module 'importlib' has no attribute 'util'

2025-09-23 23:20:40,465 - epetcare - ERROR - Failed to manually load views.main_window from C:\epetcare\vet_desktop_app\views\main_window.py: module 'importlib' has no attribute 'util'
2025-09-23 23:20:40,466 - epetcare - ERROR - Traceback (most recent call last):
  File "C:\epetcare\vet_desktop_app\module_finder.py", line 106, in ensure_modules_importable
    spec = importlib.util.spec_from_file_location(module_name, module_path)
           ^^^^^^^^^^^^^^
AttributeError: module 'importlib' has no attribute 'util'

2025-09-23 23:20:40,466 - epetcare - ERROR - Failed to manually load views.login_dialog from C:\epetcare\vet_desktop_app\views\login_dialog.py: module 'importlib' has no attribute 'util'
2025-09-23 23:20:40,467 - epetcare - ERROR - Traceback (most recent call last):
  File "C:\epetcare\vet_desktop_app\module_finder.py", line 106, in ensure_modules_importable
    spec = importlib.util.spec_from_file_location(module_name, module_path)
           ^^^^^^^^^^^^^^
AttributeError: module 'importlib' has no attribute 'util'

2025-09-23 23:20:40,467 - epetcare - ERROR - Failed to manually load views.register_dialog from C:\epetcare\vet_desktop_app\views\register_dialog.py: module 'importlib' has no attribute 'util'
2025-09-23 23:20:40,468 - epetcare - ERROR - Traceback (most recent call last):
  File "C:\epetcare\vet_desktop_app\module_finder.py", line 106, in ensure_modules_importable
    spec = importlib.util.spec_from_file_location(module_name, module_path)
           ^^^^^^^^^^^^^^
AttributeError: module 'importlib' has no attribute 'util'

2025-09-23 23:20:40,468 - epetcare - ERROR - Failed to manually load package utils: module 'importlib' has no attribute 'util'
2025-09-23 23:20:40,469 - epetcare - ERROR - Traceback (most recent call last):
  File "C:\epetcare\vet_desktop_app\module_finder.py", line 124, in ensure_modules_importable
    module = importlib.util.module_from_spec(spec)
             ^^^^^^^^^^^^^^
AttributeError: module 'importlib' has no attribute 'util'

2025-09-23 23:20:40,469 - epetcare - ERROR - Failed to manually load utils.database from C:\epetcare\vet_desktop_app\utils\database.py: module 'importlib' has no attribute 'util'
2025-09-23 23:20:40,472 - epetcare - ERROR - Traceback (most recent call last):
  File "C:\epetcare\vet_desktop_app\module_finder.py", line 106, in ensure_modules_importable
    spec = importlib.util.spec_from_file_location(module_name, module_path)
           ^^^^^^^^^^^^^^
AttributeError: module 'importlib' has no attribute 'util'

2025-09-23 23:20:40,472 - epetcare - ERROR - Failed to manually load utils.config from C:\epetcare\vet_desktop_app\utils\config.py: module 'importlib' has no attribute 'util'
2025-09-23 23:20:40,473 - epetcare - ERROR - Traceback (most recent call last):
  File "C:\epetcare\vet_desktop_app\module_finder.py", line 106, in ensure_modules_importable
    spec = importlib.util.spec_from_file_location(module_name, module_path)
           ^^^^^^^^^^^^^^
AttributeError: module 'importlib' has no attribute 'util'

2025-09-23 23:20:40,473 - epetcare - ERROR - Failed to manually load utils.notification_manager from C:\epetcare\vet_desktop_app\utils\notification_manager.py: module 'importlib' has no attribute 'util'
2025-09-23 23:20:40,474 - epetcare - ERROR - Traceback (most recent call last):
  File "C:\epetcare\vet_desktop_app\module_finder.py", line 106, in ensure_modules_importable
    spec = importlib.util.spec_from_file_location(module_name, module_path)
           ^^^^^^^^^^^^^^
AttributeError: module 'importlib' has no attribute 'util'

2025-09-23 23:20:40,474 - epetcare - WARNING - Some modules still missing: ['models.data_access', 'models.models', 'views', 'views.main_window', 'views.login_dialog', 'views.register_dialog', 'utils', 'utils.database', 'utils.config', 'utils.notification_manager']
2025-09-23 23:20:40,619 - epetcare - ERROR - Error importing view modules: No module named 'models.data_access'; 'models' is not a package
2025-09-23 23:20:40,621 - epetcare - ERROR - Traceback (most recent call last):
  File "C:\epetcare\vet_desktop_app\views\__init__.py", line 132, in <module>
    from . import main_window
  File "C:\epetcare\vet_desktop_app\views\main_window.py", line 118, in <module>
    from views.login_dialog import LoginDialog
  File "C:\epetcare\vet_desktop_app\views\login_dialog.py", line 93, in <module>
    from models.data_access import UserDataAccess, VeterinarianDataAccess
ModuleNotFoundError: No module named 'models.data_access'; 'models' is not a package

2025-09-23 23:20:40,634 - epetcare - ERROR - Failed to import application modules: No module named 'models.data_access'; 'models' is not a package
2025-09-23 23:20:40,637 - epetcare - ERROR - Traceback (most recent call last):
  File "C:\epetcare\vet_desktop_app\main.py", line 78, in <module>
    from views.main_window import MainWindow
  File "C:\epetcare\vet_desktop_app\views\main_window.py", line 118, in <module>
    from views.login_dialog import LoginDialog
  File "C:\epetcare\vet_desktop_app\views\login_dialog.py", line 93, in <module>
    from models.data_access import UserDataAccess, VeterinarianDataAccess
ModuleNotFoundError: No module named 'models.data_access'; 'models' is not a package

2025-09-23 23:20:40,637 - epetcare - ERROR - Error during startup: No module named 'models.data_access'; 'models' is not a package
2025-09-23 23:20:40,638 - epetcare - ERROR - Traceback (most recent call last):
  File "C:\epetcare\vet_desktop_app\main.py", line 78, in <module>
    from views.main_window import MainWindow
  File "C:\epetcare\vet_desktop_app\views\main_window.py", line 118, in <module>
    from views.login_dialog import LoginDialog
  File "C:\epetcare\vet_desktop_app\views\login_dialog.py", line 93, in <module>
    from models.data_access import UserDataAccess, VeterinarianDataAccess
ModuleNotFoundError: No module named 'models.data_access'; 'models' is not a package

2025-09-23 23:20:45,068 - epetcare - INFO - Starting ePetCare Vet Desktop Application
2025-09-23 23:20:45,101 - epetcare - ERROR - Failed to import module: models.data_access - No module named 'models.data_access'; 'models' is not a package
2025-09-23 23:20:45,101 - epetcare - WARNING - Some modules could not be imported. Trying alternative approaches...
2025-09-23 23:20:45,102 - epetcare - ERROR - Failed to manually load package models: module 'importlib' has no attribute 'util'
2025-09-23 23:20:45,103 - epetcare - ERROR - Traceback (most recent call last):
  File "C:\epetcare\vet_desktop_app\module_finder.py", line 124, in ensure_modules_importable
    module = importlib.util.module_from_spec(spec)
             ^^^^^^^^^^^^^^
AttributeError: module 'importlib' has no attribute 'util'

2025-09-23 23:20:45,103 - epetcare - ERROR - Failed to manually load models.data_access from C:\epetcare\vet_desktop_app\models\data_access.py: module 'importlib' has no attribute 'util'
2025-09-23 23:20:45,104 - epetcare - ERROR - Traceback (most recent call last):
  File "C:\epetcare\vet_desktop_app\module_finder.py", line 106, in ensure_modules_importable
    spec = importlib.util.spec_from_file_location(module_name, module_path)
           ^^^^^^^^^^^^^^
AttributeError: module 'importlib' has no attribute 'util'

2025-09-23 23:20:45,104 - epetcare - ERROR - Failed to manually load models.models from C:\epetcare\vet_desktop_app\models\models.py: module 'importlib' has no attribute 'util'
2025-09-23 23:20:45,104 - epetcare - ERROR - Traceback (most recent call last):
  File "C:\epetcare\vet_desktop_app\module_finder.py", line 106, in ensure_modules_importable
    spec = importlib.util.spec_from_file_location(module_name, module_path)
           ^^^^^^^^^^^^^^
AttributeError: module 'importlib' has no attribute 'util'

2025-09-23 23:20:45,105 - epetcare - ERROR - Failed to manually load package views: module 'importlib' has no attribute 'util'
2025-09-23 23:20:45,106 - epetcare - ERROR - Traceback (most recent call last):
  File "C:\epetcare\vet_desktop_app\module_finder.py", line 124, in ensure_modules_importable
    module = importlib.util.module_from_spec(spec)
             ^^^^^^^^^^^^^^
AttributeError: module 'importlib' has no attribute 'util'

2025-09-23 23:20:45,106 - epetcare - ERROR - Failed to manually load views.main_window from C:\epetcare\vet_desktop_app\views\main_window.py: module 'importlib' has no attribute 'util'
2025-09-23 23:20:45,106 - epetcare - ERROR - Traceback (most recent call last):
  File "C:\epetcare\vet_desktop_app\module_finder.py", line 106, in ensure_modules_importable
    spec = importlib.util.spec_from_file_location(module_name, module_path)
           ^^^^^^^^^^^^^^
AttributeError: module 'importlib' has no attribute 'util'

2025-09-23 23:20:45,107 - epetcare - ERROR - Failed to manually load views.login_dialog from C:\epetcare\vet_desktop_app\views\login_dialog.py: module 'importlib' has no attribute 'util'
2025-09-23 23:20:45,107 - epetcare - ERROR - Traceback (most recent call last):
  File "C:\epetcare\vet_desktop_app\module_finder.py", line 106, in ensure_modules_importable
    spec = importlib.util.spec_from_file_location(module_name, module_path)
           ^^^^^^^^^^^^^^
AttributeError: module 'importlib' has no attribute 'util'

2025-09-23 23:20:45,108 - epetcare - ERROR - Failed to manually load views.register_dialog from C:\epetcare\vet_desktop_app\views\register_dialog.py: module 'importlib' has no attribute 'util'
2025-09-23 23:20:45,108 - epetcare - ERROR - Traceback (most recent call last):
  File "C:\epetcare\vet_desktop_app\module_finder.py", line 106, in ensure_modules_importable
    spec = importlib.util.spec_from_file_location(module_name, module_path)
           ^^^^^^^^^^^^^^
AttributeError: module 'importlib' has no attribute 'util'

2025-09-23 23:20:45,109 - epetcare - ERROR - Failed to manually load package utils: module 'importlib' has no attribute 'util'
2025-09-23 23:20:45,110 - epetcare - ERROR - Traceback (most recent call last):
  File "C:\epetcare\vet_desktop_app\module_finder.py", line 124, in ensure_modules_importable
    module = importlib.util.module_from_spec(spec)
             ^^^^^^^^^^^^^^
AttributeError: module 'importlib' has no attribute 'util'

2025-09-23 23:20:45,110 - epetcare - ERROR - Failed to manually load utils.database from C:\epetcare\vet_desktop_app\utils\database.py: module 'importlib' has no attribute 'util'
2025-09-23 23:20:45,111 - epetcare - ERROR - Traceback (most recent call last):
  File "C:\epetcare\vet_desktop_app\module_finder.py", line 106, in ensure_modules_importable
    spec = importlib.util.spec_from_file_location(module_name, module_path)
           ^^^^^^^^^^^^^^
AttributeError: module 'importlib' has no attribute 'util'

2025-09-23 23:20:45,111 - epetcare - ERROR - Failed to manually load utils.config from C:\epetcare\vet_desktop_app\utils\config.py: module 'importlib' has no attribute 'util'
2025-09-23 23:20:45,111 - epetcare - ERROR - Traceback (most recent call last):
  File "C:\epetcare\vet_desktop_app\module_finder.py", line 106, in ensure_modules_importable
    spec = importlib.util.spec_from_file_location(module_name, module_path)
           ^^^^^^^^^^^^^^
AttributeError: module 'importlib' has no attribute 'util'

2025-09-23 23:20:45,112 - epetcare - ERROR - Failed to manually load utils.notification_manager from C:\epetcare\vet_desktop_app\utils\notification_manager.py: module 'importlib' has no attribute 'util'
2025-09-23 23:20:45,113 - epetcare - ERROR - Traceback (most recent call last):
  File "C:\epetcare\vet_desktop_app\module_finder.py", line 106, in ensure_modules_importable
    spec = importlib.util.spec_from_file_location(module_name, module_path)
           ^^^^^^^^^^^^^^
AttributeError: module 'importlib' has no attribute 'util'

2025-09-23 23:20:45,113 - epetcare - WARNING - Some modules still missing: ['models.data_access', 'models.models', 'views', 'views.main_window', 'views.login_dialog', 'views.register_dialog', 'utils', 'utils.database', 'utils.config', 'utils.notification_manager']
2025-09-23 23:20:45,275 - epetcare - ERROR - Error importing view modules: No module named 'models.data_access'; 'models' is not a package
2025-09-23 23:20:45,277 - epetcare - ERROR - Traceback (most recent call last):
  File "C:\epetcare\vet_desktop_app\views\__init__.py", line 132, in <module>
    from . import main_window
  File "C:\epetcare\vet_desktop_app\views\main_window.py", line 118, in <module>
    from views.login_dialog import LoginDialog
  File "C:\epetcare\vet_desktop_app\views\login_dialog.py", line 93, in <module>
    from models.data_access import UserDataAccess, VeterinarianDataAccess
ModuleNotFoundError: No module named 'models.data_access'; 'models' is not a package

2025-09-23 23:20:45,290 - epetcare - ERROR - Failed to import application modules: No module named 'models.data_access'; 'models' is not a package
2025-09-23 23:20:45,293 - epetcare - ERROR - Traceback (most recent call last):
  File "C:\epetcare\vet_desktop_app\main.py", line 78, in <module>
    from views.main_window import MainWindow
  File "C:\epetcare\vet_desktop_app\views\main_window.py", line 118, in <module>
    from views.login_dialog import LoginDialog
  File "C:\epetcare\vet_desktop_app\views\login_dialog.py", line 93, in <module>
    from models.data_access import UserDataAccess, VeterinarianDataAccess
ModuleNotFoundError: No module named 'models.data_access'; 'models' is not a package

2025-09-23 23:20:45,293 - epetcare - ERROR - Error during startup: No module named 'models.data_access'; 'models' is not a package
2025-09-23 23:20:45,294 - epetcare - ERROR - Traceback (most recent call last):
  File "C:\epetcare\vet_desktop_app\main.py", line 78, in <module>
    from views.main_window import MainWindow
  File "C:\epetcare\vet_desktop_app\views\main_window.py", line 118, in <module>
    from views.login_dialog import LoginDialog
  File "C:\epetcare\vet_desktop_app\views\login_dialog.py", line 93, in <module>
    from models.data_access import UserDataAccess, VeterinarianDataAccess
ModuleNotFoundError: No module named 'models.data_access'; 'models' is not a package

2025-09-23 23:20:53,323 - epetcare - INFO - Starting ePetCare Vet Desktop Application
2025-09-23 23:20:53,357 - epetcare - ERROR - Failed to import module: models.data_access - No module named 'models.data_access'; 'models' is not a package
2025-09-23 23:20:53,357 - epetcare - WARNING - Some modules could not be imported. Trying alternative approaches...
2025-09-23 23:20:53,357 - epetcare - ERROR - Failed to manually load package models: module 'importlib' has no attribute 'util'
2025-09-23 23:20:53,358 - epetcare - ERROR - Traceback (most recent call last):
  File "C:\epetcare\vet_desktop_app\module_finder.py", line 124, in ensure_modules_importable
    module = importlib.util.module_from_spec(spec)
             ^^^^^^^^^^^^^^
AttributeError: module 'importlib' has no attribute 'util'

2025-09-23 23:20:53,359 - epetcare - ERROR - Failed to manually load models.data_access from C:\epetcare\vet_desktop_app\models\data_access.py: module 'importlib' has no attribute 'util'
2025-09-23 23:20:53,359 - epetcare - ERROR - Traceback (most recent call last):
  File "C:\epetcare\vet_desktop_app\module_finder.py", line 106, in ensure_modules_importable
    spec = importlib.util.spec_from_file_location(module_name, module_path)
           ^^^^^^^^^^^^^^
AttributeError: module 'importlib' has no attribute 'util'

2025-09-23 23:20:53,360 - epetcare - ERROR - Failed to manually load models.models from C:\epetcare\vet_desktop_app\models\models.py: module 'importlib' has no attribute 'util'
2025-09-23 23:20:53,361 - epetcare - ERROR - Traceback (most recent call last):
  File "C:\epetcare\vet_desktop_app\module_finder.py", line 106, in ensure_modules_importable
    spec = importlib.util.spec_from_file_location(module_name, module_path)
           ^^^^^^^^^^^^^^
AttributeError: module 'importlib' has no attribute 'util'

2025-09-23 23:20:53,361 - epetcare - ERROR - Failed to manually load package views: module 'importlib' has no attribute 'util'
2025-09-23 23:20:53,362 - epetcare - ERROR - Traceback (most recent call last):
  File "C:\epetcare\vet_desktop_app\module_finder.py", line 124, in ensure_modules_importable
    module = importlib.util.module_from_spec(spec)
             ^^^^^^^^^^^^^^
AttributeError: module 'importlib' has no attribute 'util'

2025-09-23 23:20:53,362 - epetcare - ERROR - Failed to manually load views.main_window from C:\epetcare\vet_desktop_app\views\main_window.py: module 'importlib' has no attribute 'util'
2025-09-23 23:20:53,363 - epetcare - ERROR - Traceback (most recent call last):
  File "C:\epetcare\vet_desktop_app\module_finder.py", line 106, in ensure_modules_importable
    spec = importlib.util.spec_from_file_location(module_name, module_path)
           ^^^^^^^^^^^^^^
AttributeError: module 'importlib' has no attribute 'util'

2025-09-23 23:20:53,363 - epetcare - ERROR - Failed to manually load views.login_dialog from C:\epetcare\vet_desktop_app\views\login_dialog.py: module 'importlib' has no attribute 'util'
2025-09-23 23:20:53,364 - epetcare - ERROR - Traceback (most recent call last):
  File "C:\epetcare\vet_desktop_app\module_finder.py", line 106, in ensure_modules_importable
    spec = importlib.util.spec_from_file_location(module_name, module_path)
           ^^^^^^^^^^^^^^
AttributeError: module 'importlib' has no attribute 'util'

2025-09-23 23:20:53,364 - epetcare - ERROR - Failed to manually load views.register_dialog from C:\epetcare\vet_desktop_app\views\register_dialog.py: module 'importlib' has no attribute 'util'
2025-09-23 23:20:53,365 - epetcare - ERROR - Traceback (most recent call last):
  File "C:\epetcare\vet_desktop_app\module_finder.py", line 106, in ensure_modules_importable
    spec = importlib.util.spec_from_file_location(module_name, module_path)
           ^^^^^^^^^^^^^^
AttributeError: module 'importlib' has no attribute 'util'

2025-09-23 23:20:53,365 - epetcare - ERROR - Failed to manually load package utils: module 'importlib' has no attribute 'util'
2025-09-23 23:20:53,366 - epetcare - ERROR - Traceback (most recent call last):
  File "C:\epetcare\vet_desktop_app\module_finder.py", line 124, in ensure_modules_importable
    module = importlib.util.module_from_spec(spec)
             ^^^^^^^^^^^^^^
AttributeError: module 'importlib' has no attribute 'util'

2025-09-23 23:20:53,366 - epetcare - ERROR - Failed to manually load utils.database from C:\epetcare\vet_desktop_app\utils\database.py: module 'importlib' has no attribute 'util'
2025-09-23 23:20:53,367 - epetcare - ERROR - Traceback (most recent call last):
  File "C:\epetcare\vet_desktop_app\module_finder.py", line 106, in ensure_modules_importable
    spec = importlib.util.spec_from_file_location(module_name, module_path)
           ^^^^^^^^^^^^^^
AttributeError: module 'importlib' has no attribute 'util'

2025-09-23 23:20:53,367 - epetcare - ERROR - Failed to manually load utils.config from C:\epetcare\vet_desktop_app\utils\config.py: module 'importlib' has no attribute 'util'
2025-09-23 23:20:53,368 - epetcare - ERROR - Traceback (most recent call last):
  File "C:\epetcare\vet_desktop_app\module_finder.py", line 106, in ensure_modules_importable
    spec = importlib.util.spec_from_file_location(module_name, module_path)
           ^^^^^^^^^^^^^^
AttributeError: module 'importlib' has no attribute 'util'

2025-09-23 23:20:53,368 - epetcare - ERROR - Failed to manually load utils.notification_manager from C:\epetcare\vet_desktop_app\utils\notification_manager.py: module 'importlib' has no attribute 'util'
2025-09-23 23:20:53,369 - epetcare - ERROR - Traceback (most recent call last):
  File "C:\epetcare\vet_desktop_app\module_finder.py", line 106, in ensure_modules_importable
    spec = importlib.util.spec_from_file_location(module_name, module_path)
           ^^^^^^^^^^^^^^
AttributeError: module 'importlib' has no attribute 'util'

2025-09-23 23:20:53,369 - epetcare - WARNING - Some modules still missing: ['models.data_access', 'models.models', 'views', 'views.main_window', 'views.login_dialog', 'views.register_dialog', 'utils', 'utils.database', 'utils.config', 'utils.notification_manager']
2025-09-23 23:20:53,512 - epetcare - ERROR - Error importing view modules: No module named 'models.data_access'; 'models' is not a package
2025-09-23 23:20:53,513 - epetcare - ERROR - Traceback (most recent call last):
  File "C:\epetcare\vet_desktop_app\views\__init__.py", line 132, in <module>
    from . import main_window
  File "C:\epetcare\vet_desktop_app\views\main_window.py", line 118, in <module>
    from views.login_dialog import LoginDialog
  File "C:\epetcare\vet_desktop_app\views\login_dialog.py", line 93, in <module>
    from models.data_access import UserDataAccess, VeterinarianDataAccess
ModuleNotFoundError: No module named 'models.data_access'; 'models' is not a package

2025-09-23 23:20:53,526 - epetcare - ERROR - Failed to import application modules: No module named 'models.data_access'; 'models' is not a package
2025-09-23 23:20:53,529 - epetcare - ERROR - Traceback (most recent call last):
  File "C:\epetcare\vet_desktop_app\main.py", line 78, in <module>
    from views.main_window import MainWindow
  File "C:\epetcare\vet_desktop_app\views\main_window.py", line 118, in <module>
    from views.login_dialog import LoginDialog
  File "C:\epetcare\vet_desktop_app\views\login_dialog.py", line 93, in <module>
    from models.data_access import UserDataAccess, VeterinarianDataAccess
ModuleNotFoundError: No module named 'models.data_access'; 'models' is not a package

2025-09-23 23:20:53,530 - epetcare - ERROR - Error during startup: No module named 'models.data_access'; 'models' is not a package
2025-09-23 23:20:53,531 - epetcare - ERROR - Traceback (most recent call last):
  File "C:\epetcare\vet_desktop_app\main.py", line 78, in <module>
    from views.main_window import MainWindow
  File "C:\epetcare\vet_desktop_app\views\main_window.py", line 118, in <module>
    from views.login_dialog import LoginDialog
  File "C:\epetcare\vet_desktop_app\views\login_dialog.py", line 93, in <module>
    from models.data_access import UserDataAccess, VeterinarianDataAccess
ModuleNotFoundError: No module named 'models.data_access'; 'models' is not a package

2025-09-23 23:26:59,779 - epetcare - INFO - Starting ePetCare Vet Desktop Application
2025-09-23 23:26:59,780 - epetcare - WARNING - Could not import module_finder. Continuing without it.
2025-09-23 23:27:00,013 - epetcare - ERROR - Error during startup: name 'TreatmentType' is not defined
2025-09-23 23:27:00,020 - epetcare - ERROR - Traceback (most recent call last):
  File "C:\epetcare\vet_desktop_app\main.py", line 72, in <module>
    import views
  File "C:\epetcare\vet_desktop_app\views\__init__.py", line 132, in <module>
    from . import main_window
  File "C:\epetcare\vet_desktop_app\views\main_window.py", line 118, in <module>
    from views.login_dialog import LoginDialog
  File "C:\epetcare\vet_desktop_app\views\login_dialog.py", line 93, in <module>
    from models.data_access import UserDataAccess, VeterinarianDataAccess
  File "C:\epetcare\vet_desktop_app\models\__init__.py", line 90, in <module>
    from . import data_access
  File "C:\epetcare\vet_desktop_app\models\data_access.py", line 933, in <module>
    class TreatmentTypeDataAccess(DataAccessBase):
    ...<68 lines>...
            return self.db.update('vet_treatmenttype', data, treatment_type.id)
  File "C:\epetcare\vet_desktop_app\models\data_access.py", line 936, in TreatmentTypeDataAccess
    def get_by_id(self, treatment_type_id: int) -> Optional[TreatmentType]:
                                                            ^^^^^^^^^^^^^
NameError: name 'TreatmentType' is not defined. Did you mean: 'Treatment'?

2025-09-23 23:27:15,204 - epetcare - INFO - Starting ePetCare Vet Desktop Application
2025-09-23 23:27:15,204 - epetcare - WARNING - Could not import module_finder. Continuing without it.
2025-09-23 23:27:15,388 - epetcare - ERROR - Error during startup: name 'TreatmentType' is not defined
2025-09-23 23:27:15,393 - epetcare - ERROR - Traceback (most recent call last):
  File "C:\epetcare\vet_desktop_app\main.py", line 72, in <module>
    import views
  File "C:\epetcare\vet_desktop_app\views\__init__.py", line 132, in <module>
    from . import main_window
  File "C:\epetcare\vet_desktop_app\views\main_window.py", line 118, in <module>
    from views.login_dialog import LoginDialog
  File "C:\epetcare\vet_desktop_app\views\login_dialog.py", line 93, in <module>
    from models.data_access import UserDataAccess, VeterinarianDataAccess
  File "C:\epetcare\vet_desktop_app\models\__init__.py", line 90, in <module>
    from . import data_access
  File "C:\epetcare\vet_desktop_app\models\data_access.py", line 933, in <module>
    class TreatmentTypeDataAccess(DataAccessBase):
    ...<68 lines>...
            return self.db.update('vet_treatmenttype', data, treatment_type.id)
  File "C:\epetcare\vet_desktop_app\models\data_access.py", line 936, in TreatmentTypeDataAccess
    def get_by_id(self, treatment_type_id: int) -> Optional[TreatmentType]:
                                                            ^^^^^^^^^^^^^
NameError: name 'TreatmentType' is not defined. Did you mean: 'Treatment'?

2025-09-23 23:37:43,036 - epetcare - INFO - Starting ePetCare Vet Desktop Application
2025-09-23 23:37:43,037 - epetcare - WARNING - Could not import module_finder. Continuing without it.
2025-09-23 23:37:43,320 - epetcare - ERROR - Error during startup: name 'Schedule' is not defined
2025-09-23 23:37:43,383 - epetcare - ERROR - Traceback (most recent call last):
  File "C:\epetcare\vet_desktop_app\main.py", line 72, in <module>
    import views
  File "C:\epetcare\vet_desktop_app\views\__init__.py", line 132, in <module>
    from . import main_window
  File "C:\epetcare\vet_desktop_app\views\main_window.py", line 118, in <module>
    from views.login_dialog import LoginDialog
  File "C:\epetcare\vet_desktop_app\views\login_dialog.py", line 93, in <module>
    from models.data_access import UserDataAccess, VeterinarianDataAccess
  File "C:\epetcare\vet_desktop_app\models\__init__.py", line 90, in <module>
    from . import data_access
  File "C:\epetcare\vet_desktop_app\models\data_access.py", line 1009, in <module>
    class ScheduleDataAccess(DataAccessBase):
    ...<52 lines>...
            return self.db.delete('vet_schedule', schedule_id)
  File "C:\epetcare\vet_desktop_app\models\data_access.py", line 1012, in ScheduleDataAccess
    def get_by_vet(self, vet_id: int) -> List[Schedule]:
                                              ^^^^^^^^
NameError: name 'Schedule' is not defined

2025-09-23 23:38:01,002 - epetcare - INFO - Starting ePetCare Vet Desktop Application
2025-09-23 23:38:01,003 - epetcare - WARNING - Could not import module_finder. Continuing without it.
2025-09-23 23:38:01,196 - epetcare - ERROR - Error during startup: name 'Schedule' is not defined
2025-09-23 23:38:01,202 - epetcare - ERROR - Traceback (most recent call last):
  File "C:\epetcare\vet_desktop_app\main.py", line 72, in <module>
    import views
  File "C:\epetcare\vet_desktop_app\views\__init__.py", line 132, in <module>
    from . import main_window
  File "C:\epetcare\vet_desktop_app\views\main_window.py", line 118, in <module>
    from views.login_dialog import LoginDialog
  File "C:\epetcare\vet_desktop_app\views\login_dialog.py", line 93, in <module>
    from models.data_access import UserDataAccess, VeterinarianDataAccess
  File "C:\epetcare\vet_desktop_app\models\__init__.py", line 90, in <module>
    from . import data_access
  File "C:\epetcare\vet_desktop_app\models\data_access.py", line 1009, in <module>
    class ScheduleDataAccess(DataAccessBase):
    ...<52 lines>...
            return self.db.delete('vet_schedule', schedule_id)
  File "C:\epetcare\vet_desktop_app\models\data_access.py", line 1012, in ScheduleDataAccess
    def get_by_vet(self, vet_id: int) -> List[Schedule]:
                                              ^^^^^^^^
NameError: name 'Schedule' is not defined

2025-09-23 23:39:50,463 - epetcare - INFO - Starting ePetCare Vet Desktop Application
2025-09-23 23:39:50,464 - epetcare - WARNING - Could not import module_finder. Continuing without it.
2025-09-23 23:39:50,760 - epetcare - INFO - Initializing application...
2025-09-23 23:39:50,816 - epetcare - WARNING - vet_notification table not found, attempting to create it
2025-09-23 23:39:50,831 - epetcare - INFO - Created vet_notification table successfully
2025-09-23 23:39:50,831 - epetcare - INFO - Database connection established successfully
2025-09-23 23:39:50,831 - epetcare - INFO - Creating main window...
2025-09-23 23:41:19,240 - epetcare - INFO - Application started successfully
2025-09-24 00:13:38,776 - epetcare - INFO - Starting ePetCare Vet Desktop Application
2025-09-24 00:13:38,777 - epetcare - WARNING - Could not import module_finder. Continuing without it.
2025-09-24 00:13:39,046 - epetcare - INFO - Initializing application...
2025-09-24 00:13:39,086 - epetcare - INFO - Database connection established successfully
2025-09-24 00:13:39,086 - epetcare - INFO - Creating main window...
2025-09-24 00:14:07,388 - epetcare - INFO - Application started successfully
2025-09-24 00:17:11,054 - epetcare - INFO - Starting ePetCare Vet Desktop Application
2025-09-24 00:17:11,055 - epetcare - WARNING - Could not import module_finder. Continuing without it.
2025-09-24 00:17:11,256 - epetcare - INFO - Initializing application...
2025-09-24 00:17:11,280 - epetcare - INFO - Database connection established successfully
2025-09-24 00:17:11,280 - epetcare - INFO - Creating main window...
2025-09-24 00:17:17,403 - epetcare - INFO - Application started successfully
2025-09-24 00:21:40,559 - epetcare - INFO - Starting ePetCare Vet Desktop Application
2025-09-24 00:21:40,560 - epetcare - WARNING - Could not import module_finder. Continuing without it.
2025-09-24 00:21:40,793 - epetcare - INFO - Initializing application...
2025-09-24 00:21:40,819 - epetcare - INFO - Real-time database synchronization enabled
2025-09-24 00:21:40,819 - epetcare - INFO - Database sync manager set up with main DB: C:\epetcare\db.sqlite3, local DB: C:\epetcare\db.sqlite3
2025-09-24 00:21:40,819 - epetcare - INFO - Database sync thread started
2025-09-24 00:21:40,822 - epetcare - WARNING - vet_notification table not found, attempting to create it
2025-09-24 00:21:40,836 - epetcare - INFO - Created vet_notification table successfully
2025-09-24 00:21:40,837 - epetcare - INFO - Database connection established successfully
2025-09-24 00:21:40,838 - epetcare - INFO - Creating main window...
2025-09-24 00:21:45,674 - epetcare - INFO - Application started successfully
2025-09-24 00:22:04,193 - epetcare - INFO - Starting ePetCare Vet Desktop Application
2025-09-24 00:22:04,193 - epetcare - WARNING - Could not import module_finder. Continuing without it.
2025-09-24 00:22:04,415 - epetcare - INFO - Initializing application...
2025-09-24 00:22:04,446 - epetcare - INFO - Real-time database synchronization enabled
2025-09-24 00:22:04,447 - epetcare - INFO - Database sync manager set up with main DB: C:\epetcare\db.sqlite3, local DB: C:\epetcare\db.sqlite3
2025-09-24 00:22:04,447 - epetcare - INFO - Database sync thread started
2025-09-24 00:22:04,451 - epetcare - INFO - Database connection established successfully
2025-09-24 00:22:04,452 - epetcare - INFO - Creating main window...
2025-09-24 00:22:19,381 - epetcare - INFO - Application started successfully
2025-09-24 00:44:03,029 - epetcare - INFO - Starting ePetCare Vet Desktop Application
2025-09-24 00:44:03,030 - epetcare - WARNING - Could not import module_finder. Continuing without it.
2025-09-24 00:44:03,211 - epetcare - ERROR - Error during startup: expected 'except' or 'finally' block (database.py, line 90)
2025-09-24 00:44:03,216 - epetcare - ERROR - Traceback (most recent call last):
  File "C:\epetcare\vet_desktop_app\main.py", line 72, in <module>
    import views
  File "C:\epetcare\vet_desktop_app\views\__init__.py", line 132, in <module>
    from . import main_window
  File "C:\epetcare\vet_desktop_app\views\main_window.py", line 118, in <module>
    from views.login_dialog import LoginDialog
  File "C:\epetcare\vet_desktop_app\views\login_dialog.py", line 93, in <module>
    from models.data_access import UserDataAccess, VeterinarianDataAccess
  File "C:\epetcare\vet_desktop_app\models\__init__.py", line 90, in <module>
    from . import data_access
  File "C:\epetcare\vet_desktop_app\models\data_access.py", line 105, in <module>
    from utils.database import DatabaseManager
  File "C:\epetcare\vet_desktop_app\utils\__init__.py", line 7, in <module>
    from . import database
  File "C:\epetcare\vet_desktop_app\utils\database.py", line 90
    cursor = db_connection.cursor()
    ^^^^^^
SyntaxError: expected 'except' or 'finally' block

2025-09-24 01:17:35,644 - epetcare - INFO - Starting ePetCare Vet Desktop Application
2025-09-24 01:17:35,645 - epetcare - WARNING - Could not import module_finder. Continuing without it.
2025-09-24 01:17:35,837 - epetcare - ERROR - Error during startup: expected 'except' or 'finally' block (database.py, line 90)
2025-09-24 01:17:35,842 - epetcare - ERROR - Traceback (most recent call last):
  File "C:\epetcare\vet_desktop_app\main.py", line 72, in <module>
    import views
  File "C:\epetcare\vet_desktop_app\views\__init__.py", line 132, in <module>
    from . import main_window
  File "C:\epetcare\vet_desktop_app\views\main_window.py", line 118, in <module>
    from views.login_dialog import LoginDialog
  File "C:\epetcare\vet_desktop_app\views\login_dialog.py", line 93, in <module>
    from models.data_access import UserDataAccess, VeterinarianDataAccess
  File "C:\epetcare\vet_desktop_app\models\__init__.py", line 90, in <module>
    from . import data_access
  File "C:\epetcare\vet_desktop_app\models\data_access.py", line 105, in <module>
    from utils.database import DatabaseManager
  File "C:\epetcare\vet_desktop_app\utils\__init__.py", line 7, in <module>
    from . import database
  File "C:\epetcare\vet_desktop_app\utils\database.py", line 90
    cursor = db_connection.cursor()
    ^^^^^^
SyntaxError: expected 'except' or 'finally' block

2025-09-24 01:17:55,913 - epetcare - INFO - Starting ePetCare Vet Desktop Application
2025-09-24 01:17:55,914 - epetcare - WARNING - Could not import module_finder. Continuing without it.
2025-09-24 01:17:56,109 - epetcare - ERROR - Error during startup: expected 'except' or 'finally' block (database.py, line 90)
2025-09-24 01:17:56,116 - epetcare - ERROR - Traceback (most recent call last):
  File "C:\epetcare\vet_desktop_app\main.py", line 72, in <module>
    import views
  File "C:\epetcare\vet_desktop_app\views\__init__.py", line 132, in <module>
    from . import main_window
  File "C:\epetcare\vet_desktop_app\views\main_window.py", line 118, in <module>
    from views.login_dialog import LoginDialog
  File "C:\epetcare\vet_desktop_app\views\login_dialog.py", line 93, in <module>
    from models.data_access import UserDataAccess, VeterinarianDataAccess
  File "C:\epetcare\vet_desktop_app\models\__init__.py", line 90, in <module>
    from . import data_access
  File "C:\epetcare\vet_desktop_app\models\data_access.py", line 105, in <module>
    from utils.database import DatabaseManager
  File "C:\epetcare\vet_desktop_app\utils\__init__.py", line 7, in <module>
    from . import database
  File "C:\epetcare\vet_desktop_app\utils\database.py", line 90
    cursor = db_connection.cursor()
    ^^^^^^
SyntaxError: expected 'except' or 'finally' block

2025-09-24 01:18:08,222 - epetcare - INFO - Starting ePetCare Vet Desktop Application
2025-09-24 01:18:08,223 - epetcare - WARNING - Could not import module_finder. Continuing without it.
2025-09-24 01:18:08,404 - epetcare - ERROR - Error during startup: expected 'except' or 'finally' block (database.py, line 90)
2025-09-24 01:18:08,409 - epetcare - ERROR - Traceback (most recent call last):
  File "C:\epetcare\vet_desktop_app\main.py", line 72, in <module>
    import views
  File "C:\epetcare\vet_desktop_app\views\__init__.py", line 132, in <module>
    from . import main_window
  File "C:\epetcare\vet_desktop_app\views\main_window.py", line 118, in <module>
    from views.login_dialog import LoginDialog
  File "C:\epetcare\vet_desktop_app\views\login_dialog.py", line 93, in <module>
    from models.data_access import UserDataAccess, VeterinarianDataAccess
  File "C:\epetcare\vet_desktop_app\models\__init__.py", line 90, in <module>
    from . import data_access
  File "C:\epetcare\vet_desktop_app\models\data_access.py", line 105, in <module>
    from utils.database import DatabaseManager
  File "C:\epetcare\vet_desktop_app\utils\__init__.py", line 7, in <module>
    from . import database
  File "C:\epetcare\vet_desktop_app\utils\database.py", line 90
    cursor = db_connection.cursor()
    ^^^^^^
SyntaxError: expected 'except' or 'finally' block

2025-09-24 01:18:12,901 - epetcare - INFO - Starting ePetCare Vet Desktop Application
2025-09-24 01:18:12,902 - epetcare - WARNING - Could not import module_finder. Continuing without it.
2025-09-24 01:18:13,107 - epetcare - ERROR - Error during startup: expected 'except' or 'finally' block (database.py, line 90)
2025-09-24 01:18:13,113 - epetcare - ERROR - Traceback (most recent call last):
  File "C:\epetcare\vet_desktop_app\main.py", line 72, in <module>
    import views
  File "C:\epetcare\vet_desktop_app\views\__init__.py", line 132, in <module>
    from . import main_window
  File "C:\epetcare\vet_desktop_app\views\main_window.py", line 118, in <module>
    from views.login_dialog import LoginDialog
  File "C:\epetcare\vet_desktop_app\views\login_dialog.py", line 93, in <module>
    from models.data_access import UserDataAccess, VeterinarianDataAccess
  File "C:\epetcare\vet_desktop_app\models\__init__.py", line 90, in <module>
    from . import data_access
  File "C:\epetcare\vet_desktop_app\models\data_access.py", line 105, in <module>
    from utils.database import DatabaseManager
  File "C:\epetcare\vet_desktop_app\utils\__init__.py", line 7, in <module>
    from . import database
  File "C:\epetcare\vet_desktop_app\utils\database.py", line 90
    cursor = db_connection.cursor()
    ^^^^^^
SyntaxError: expected 'except' or 'finally' block

2025-09-24 01:22:34,267 - epetcare - INFO - Starting ePetCare Vet Desktop Application
2025-09-24 01:22:34,268 - epetcare - WARNING - Could not import module_finder. Continuing without it.
2025-09-24 01:22:34,435 - epetcare - ERROR - Error during startup: invalid syntax (database.py, line 172)
2025-09-24 01:22:34,439 - epetcare - ERROR - Traceback (most recent call last):
  File "C:\epetcare\vet_desktop_app\main.py", line 72, in <module>
    import views
  File "C:\epetcare\vet_desktop_app\views\__init__.py", line 132, in <module>
    from . import main_window
  File "C:\epetcare\vet_desktop_app\views\main_window.py", line 118, in <module>
    from views.login_dialog import LoginDialog
  File "C:\epetcare\vet_desktop_app\views\login_dialog.py", line 93, in <module>
    from models.data_access import UserDataAccess, VeterinarianDataAccess
  File "C:\epetcare\vet_desktop_app\models\__init__.py", line 90, in <module>
    from . import data_access
  File "C:\epetcare\vet_desktop_app\models\data_access.py", line 105, in <module>
    from utils.database import DatabaseManager
  File "C:\epetcare\vet_desktop_app\utils\__init__.py", line 7, in <module>
    from . import database
  File "C:\epetcare\vet_desktop_app\utils\database.py", line 172
    except sqlite3.Error as e:
    ^^^^^^
SyntaxError: invalid syntax

2025-09-24 01:22:46,072 - epetcare - INFO - Starting ePetCare Vet Desktop Application
2025-09-24 01:22:46,072 - epetcare - WARNING - Could not import module_finder. Continuing without it.
2025-09-24 01:22:46,243 - epetcare - ERROR - Error during startup: invalid syntax (database.py, line 172)
2025-09-24 01:22:46,248 - epetcare - ERROR - Traceback (most recent call last):
  File "C:\epetcare\vet_desktop_app\main.py", line 72, in <module>
    import views
  File "C:\epetcare\vet_desktop_app\views\__init__.py", line 132, in <module>
    from . import main_window
  File "C:\epetcare\vet_desktop_app\views\main_window.py", line 118, in <module>
    from views.login_dialog import LoginDialog
  File "C:\epetcare\vet_desktop_app\views\login_dialog.py", line 93, in <module>
    from models.data_access import UserDataAccess, VeterinarianDataAccess
  File "C:\epetcare\vet_desktop_app\models\__init__.py", line 90, in <module>
    from . import data_access
  File "C:\epetcare\vet_desktop_app\models\data_access.py", line 105, in <module>
    from utils.database import DatabaseManager
  File "C:\epetcare\vet_desktop_app\utils\__init__.py", line 7, in <module>
    from . import database
  File "C:\epetcare\vet_desktop_app\utils\database.py", line 172
    except sqlite3.Error as e:
    ^^^^^^
SyntaxError: invalid syntax

2025-09-24 01:24:12,708 - epetcare - INFO - Starting ePetCare Vet Desktop Application
2025-09-24 01:24:12,709 - epetcare - WARNING - Could not import module_finder. Continuing without it.
2025-09-24 01:24:12,909 - epetcare - ERROR - Error during startup: invalid syntax (database.py, line 172)
2025-09-24 01:24:12,914 - epetcare - ERROR - Traceback (most recent call last):
  File "C:\epetcare\vet_desktop_app\main.py", line 72, in <module>
    import views
  File "C:\epetcare\vet_desktop_app\views\__init__.py", line 132, in <module>
    from . import main_window
  File "C:\epetcare\vet_desktop_app\views\main_window.py", line 118, in <module>
    from views.login_dialog import LoginDialog
  File "C:\epetcare\vet_desktop_app\views\login_dialog.py", line 93, in <module>
    from models.data_access import UserDataAccess, VeterinarianDataAccess
  File "C:\epetcare\vet_desktop_app\models\__init__.py", line 90, in <module>
    from . import data_access
  File "C:\epetcare\vet_desktop_app\models\data_access.py", line 105, in <module>
    from utils.database import DatabaseManager
  File "C:\epetcare\vet_desktop_app\utils\__init__.py", line 7, in <module>
    from . import database
  File "C:\epetcare\vet_desktop_app\utils\database.py", line 172
    except sqlite3.Error as e:
    ^^^^^^
SyntaxError: invalid syntax

2025-09-24 01:24:15,880 - epetcare - INFO - Starting ePetCare Vet Desktop Application
2025-09-24 01:24:15,880 - epetcare - WARNING - Could not import module_finder. Continuing without it.
2025-09-24 01:24:16,120 - epetcare - ERROR - Error during startup: invalid syntax (database.py, line 172)
2025-09-24 01:24:16,127 - epetcare - ERROR - Traceback (most recent call last):
  File "C:\epetcare\vet_desktop_app\main.py", line 72, in <module>
    import views
  File "C:\epetcare\vet_desktop_app\views\__init__.py", line 132, in <module>
    from . import main_window
  File "C:\epetcare\vet_desktop_app\views\main_window.py", line 118, in <module>
    from views.login_dialog import LoginDialog
  File "C:\epetcare\vet_desktop_app\views\login_dialog.py", line 93, in <module>
    from models.data_access import UserDataAccess, VeterinarianDataAccess
  File "C:\epetcare\vet_desktop_app\models\__init__.py", line 90, in <module>
    from . import data_access
  File "C:\epetcare\vet_desktop_app\models\data_access.py", line 105, in <module>
    from utils.database import DatabaseManager
  File "C:\epetcare\vet_desktop_app\utils\__init__.py", line 7, in <module>
    from . import database
  File "C:\epetcare\vet_desktop_app\utils\database.py", line 172
    except sqlite3.Error as e:
    ^^^^^^
SyntaxError: invalid syntax

2025-09-24 01:38:13,036 - epetcare - INFO - Starting ePetCare Vet Desktop Application
2025-09-24 01:38:13,036 - epetcare - WARNING - Could not import module_finder. Continuing without it.
2025-09-24 01:38:13,207 - epetcare - ERROR - Error during startup: invalid syntax (database.py, line 172)
2025-09-24 01:38:13,212 - epetcare - ERROR - Traceback (most recent call last):
  File "C:\epetcare\vet_desktop_app\main.py", line 72, in <module>
    import views
  File "C:\epetcare\vet_desktop_app\views\__init__.py", line 132, in <module>
    from . import main_window
  File "C:\epetcare\vet_desktop_app\views\main_window.py", line 118, in <module>
    from views.login_dialog import LoginDialog
  File "C:\epetcare\vet_desktop_app\views\login_dialog.py", line 93, in <module>
    from models.data_access import UserDataAccess, VeterinarianDataAccess
  File "C:\epetcare\vet_desktop_app\models\__init__.py", line 90, in <module>
    from . import data_access
  File "C:\epetcare\vet_desktop_app\models\data_access.py", line 105, in <module>
    from utils.database import DatabaseManager
  File "C:\epetcare\vet_desktop_app\utils\__init__.py", line 7, in <module>
    from . import database
  File "C:\epetcare\vet_desktop_app\utils\database.py", line 172
    except sqlite3.Error as e:
    ^^^^^^
SyntaxError: invalid syntax

2025-09-24 01:52:30,728 - epetcare - INFO - Starting ePetCare Vet Desktop Application
2025-09-24 01:52:30,729 - epetcare - WARNING - Could not import module_finder. Continuing without it.
2025-09-24 01:52:30,877 - epetcare - ERROR - Error during startup: invalid syntax (database.py, line 172)
2025-09-24 01:52:30,881 - epetcare - ERROR - Traceback (most recent call last):
  File "C:\epetcare\vet_desktop_app\main.py", line 72, in <module>
    import views
  File "C:\epetcare\vet_desktop_app\views\__init__.py", line 7, in <module>
    from . import main_window
  File "C:\epetcare\vet_desktop_app\views\main_window.py", line 118, in <module>
    from views.login_dialog import LoginDialog
  File "C:\epetcare\vet_desktop_app\views\login_dialog.py", line 93, in <module>
    from models.data_access import UserDataAccess, VeterinarianDataAccess
  File "C:\epetcare\vet_desktop_app\models\data_access.py", line 105, in <module>
    from utils.database import DatabaseManager
  File "C:\epetcare\vet_desktop_app\utils\__init__.py", line 7, in <module>
    from . import database
  File "C:\epetcare\vet_desktop_app\utils\database.py", line 172
    except sqlite3.Error as e:
    ^^^^^^
SyntaxError: invalid syntax

2025-09-24 01:56:06,834 - epetcare - INFO - Starting ePetCare Vet Desktop Application
2025-09-24 01:56:06,834 - epetcare - WARNING - Could not import module_finder. Continuing without it.
2025-09-24 01:56:07,010 - epetcare - ERROR - Error during startup: invalid syntax (database.py, line 172)
2025-09-24 01:56:07,014 - epetcare - ERROR - Traceback (most recent call last):
  File "main.py", line 72, in <module>
    import views
  File "C:\epetcare\vet_desktop_app\views\__init__.py", line 7, in <module>
    from . import main_window
  File "C:\epetcare\vet_desktop_app\views\main_window.py", line 118, in <module>
    from views.login_dialog import LoginDialog
  File "C:\epetcare\vet_desktop_app\views\login_dialog.py", line 93, in <module>
    from models.data_access import UserDataAccess, VeterinarianDataAccess
  File "C:\epetcare\vet_desktop_app\models\data_access.py", line 105, in <module>
    from utils.database import DatabaseManager
  File "C:\epetcare\vet_desktop_app\utils\__init__.py", line 7, in <module>
    from . import database
  File "C:\epetcare\vet_desktop_app\utils\database.py", line 172
    except sqlite3.Error as e:
    ^^^^^^
SyntaxError: invalid syntax

2025-09-24 01:56:13,413 - epetcare - INFO - Starting ePetCare Vet Desktop Application
2025-09-24 01:56:13,414 - epetcare - WARNING - Could not import module_finder. Continuing without it.
2025-09-24 01:56:13,576 - epetcare - ERROR - Error during startup: invalid syntax (database.py, line 172)
2025-09-24 01:56:13,580 - epetcare - ERROR - Traceback (most recent call last):
  File "main.py", line 72, in <module>
    import views
  File "C:\epetcare\vet_desktop_app\views\__init__.py", line 7, in <module>
    from . import main_window
  File "C:\epetcare\vet_desktop_app\views\main_window.py", line 118, in <module>
    from views.login_dialog import LoginDialog
  File "C:\epetcare\vet_desktop_app\views\login_dialog.py", line 93, in <module>
    from models.data_access import UserDataAccess, VeterinarianDataAccess
  File "C:\epetcare\vet_desktop_app\models\data_access.py", line 105, in <module>
    from utils.database import DatabaseManager
  File "C:\epetcare\vet_desktop_app\utils\__init__.py", line 7, in <module>
    from . import database
  File "C:\epetcare\vet_desktop_app\utils\database.py", line 172
    except sqlite3.Error as e:
    ^^^^^^
SyntaxError: invalid syntax

2025-09-24 02:20:23,602 - epetcare - INFO - Starting ePetCare Vet Desktop Application
2025-09-24 02:20:23,603 - epetcare - WARNING - Could not import module_finder. Continuing without it.
2025-09-24 02:20:23,775 - epetcare - ERROR - Failed to import application modules: cannot import name 'get_connection' from 'utils.database' (C:\epetcare\vet_desktop_app\utils\database.py)
2025-09-24 02:20:23,778 - epetcare - ERROR - Traceback (most recent call last):
  File "main.py", line 78, in <module>
    from views.main_window import MainWindow
  File "C:\epetcare\vet_desktop_app\views\main_window.py", line 118, in <module>
    from views.login_dialog import LoginDialog
  File "C:\epetcare\vet_desktop_app\views\login_dialog.py", line 94, in <module>
    from utils.database import get_connection
ImportError: cannot import name 'get_connection' from 'utils.database' (C:\epetcare\vet_desktop_app\utils\database.py)

2025-09-24 02:20:23,778 - epetcare - ERROR - Error during startup: cannot import name 'get_connection' from 'utils.database' (C:\epetcare\vet_desktop_app\utils\database.py)
2025-09-24 02:20:23,779 - epetcare - ERROR - Traceback (most recent call last):
  File "main.py", line 78, in <module>
    from views.main_window import MainWindow
  File "C:\epetcare\vet_desktop_app\views\main_window.py", line 118, in <module>
    from views.login_dialog import LoginDialog
  File "C:\epetcare\vet_desktop_app\views\login_dialog.py", line 94, in <module>
    from utils.database import get_connection
ImportError: cannot import name 'get_connection' from 'utils.database' (C:\epetcare\vet_desktop_app\utils\database.py)

2025-09-24 02:22:14,257 - epetcare - INFO - Starting ePetCare Vet Desktop Application
2025-09-24 02:22:14,257 - epetcare - WARNING - Could not import module_finder. Continuing without it.
2025-09-24 02:22:14,447 - epetcare - INFO - Initializing application...
2025-09-24 02:22:14,468 - epetcare - WARNING - Stylesheet not found in any of the checked locations
2025-09-24 02:22:14,469 - epetcare - INFO - Real-time database synchronization enabled
2025-09-24 02:22:14,469 - epetcare - INFO - Database sync manager set up with main DB: C:\epetcare\db.sqlite3, local DB: C:\epetcare\db.sqlite3
2025-09-24 02:22:14,470 - epetcare - INFO - Database sync thread started
2025-09-24 02:22:14,470 - epetcare - INFO - Setting up database connection to C:\epetcare\db.sqlite3
2025-09-24 02:22:14,493 - epetcare - INFO - Database connection established successfully
2025-09-24 02:22:14,493 - epetcare - INFO - Creating main window...
2025-09-24 02:22:40,192 - epetcare - INFO - Application started successfully
2025-09-24 02:23:11,901 - epetcare - INFO - Starting ePetCare Vet Desktop Application
2025-09-24 02:23:11,902 - epetcare - WARNING - Could not import module_finder. Continuing without it.
2025-09-24 02:23:12,090 - epetcare - INFO - Initializing application...
2025-09-24 02:23:12,111 - epetcare - WARNING - Stylesheet not found in any of the checked locations
2025-09-24 02:23:12,112 - epetcare - INFO - Real-time database synchronization enabled
2025-09-24 02:23:12,112 - epetcare - INFO - Database sync manager set up with main DB: C:\epetcare\db.sqlite3, local DB: C:\epetcare\db.sqlite3
2025-09-24 02:23:12,113 - epetcare - INFO - Database sync thread started
2025-09-24 02:23:12,113 - epetcare - INFO - Setting up database connection to C:\epetcare\db.sqlite3
2025-09-24 02:23:12,116 - epetcare - INFO - Database connection established successfully
2025-09-24 02:23:12,116 - epetcare - INFO - Creating main window...
2025-09-24 02:25:57,516 - epetcare - INFO - Starting ePetCare Vet Desktop Application
2025-09-24 02:25:57,517 - epetcare - WARNING - Could not import module_finder. Continuing without it.
2025-09-24 02:25:57,694 - epetcare - INFO - Initializing application...
2025-09-24 02:25:57,714 - epetcare - WARNING - Stylesheet not found in any of the checked locations
2025-09-24 02:25:57,716 - epetcare - INFO - Real-time database synchronization enabled
2025-09-24 02:25:57,716 - epetcare - INFO - Database sync manager set up with main DB: C:\epetcare\db.sqlite3, local DB: C:\epetcare\db.sqlite3
2025-09-24 02:25:57,716 - epetcare - INFO - Database sync thread started
2025-09-24 02:25:57,717 - epetcare - INFO - Setting up database connection to C:\epetcare\db.sqlite3
2025-09-24 02:25:57,721 - epetcare - INFO - Database connection established successfully
2025-09-24 02:25:57,721 - epetcare - INFO - Creating main window...
2025-09-24 02:26:50,183 - epetcare - INFO - Application started successfully
2025-09-24 02:29:19,166 - epetcare - INFO - Starting ePetCare Vet Desktop Application
2025-09-24 02:29:19,167 - epetcare - WARNING - Could not import module_finder. Continuing without it.
2025-09-24 02:29:19,357 - epetcare - INFO - Initializing application...
2025-09-24 02:29:19,377 - epetcare - WARNING - Stylesheet not found in any of the checked locations
2025-09-24 02:29:19,378 - epetcare - INFO - Real-time database synchronization enabled
2025-09-24 02:29:19,378 - epetcare - INFO - Database sync manager set up with main DB: C:\epetcare\db.sqlite3, local DB: C:\epetcare\db.sqlite3
2025-09-24 02:29:19,379 - epetcare - INFO - Database sync thread started
2025-09-24 02:29:19,379 - epetcare - INFO - Setting up database connection to C:\epetcare\db.sqlite3
2025-09-24 02:29:19,382 - epetcare - INFO - Database connection established successfully
2025-09-24 02:29:19,382 - epetcare - INFO - Creating main window...
2025-09-24 02:30:05,575 - epetcare - INFO - Application started successfully
2025-09-24 02:45:48,901 - epetcare - INFO - Starting ePetCare Vet Desktop Application
2025-09-24 02:45:48,902 - epetcare - WARNING - Could not import module_finder. Continuing without it.
2025-09-24 02:45:49,106 - epetcare - INFO - Initializing application...
2025-09-24 02:45:49,126 - epetcare - WARNING - Stylesheet not found in any of the checked locations
2025-09-24 02:45:49,127 - epetcare - INFO - Real-time database synchronization enabled
2025-09-24 02:45:49,127 - epetcare - INFO - Database sync manager set up with main DB: C:\epetcare\db.sqlite3, local DB: C:\epetcare\db.sqlite3
2025-09-24 02:45:49,128 - epetcare - INFO - Database sync thread started
2025-09-24 02:45:49,128 - epetcare - INFO - Setting up database connection to C:\epetcare\db.sqlite3
2025-09-24 02:45:49,131 - epetcare - INFO - Database connection established successfully
2025-09-24 02:45:49,131 - epetcare - INFO - Creating main window...
2025-09-24 02:46:10,347 - epetcare - INFO - Application started successfully
2025-09-24 02:48:48,350 - epetcare - INFO - Starting ePetCare Vet Desktop Application
2025-09-24 02:48:48,351 - epetcare - WARNING - Could not import module_finder. Continuing without it.
2025-09-24 02:48:48,546 - epetcare - INFO - Initializing application...
2025-09-24 02:48:48,566 - epetcare - WARNING - Stylesheet not found in any of the checked locations
2025-09-24 02:48:48,567 - epetcare - INFO - Real-time database synchronization enabled
2025-09-24 02:48:48,567 - epetcare - INFO - Database sync manager set up with main DB: C:\epetcare\db.sqlite3, local DB: C:\epetcare\db.sqlite3
2025-09-24 02:48:48,568 - epetcare - INFO - Database sync thread started
2025-09-24 02:48:48,568 - epetcare - INFO - Setting up database connection to C:\epetcare\db.sqlite3
2025-09-24 02:48:48,571 - epetcare - INFO - Database connection established successfully
2025-09-24 02:48:48,572 - epetcare - INFO - Creating main window...
2025-09-24 02:48:54,345 - epetcare - INFO - Application started successfully
2025-09-24 03:05:01,791 - epetcare - INFO - Starting ePetCare Vet Desktop Application
2025-09-24 03:05:01,792 - epetcare - WARNING - Could not import module_finder. Continuing without it.
2025-09-24 03:05:01,977 - epetcare - INFO - Initializing application...
2025-09-24 03:05:02,002 - epetcare - WARNING - Stylesheet not found in any of the checked locations
2025-09-24 03:05:02,003 - epetcare - INFO - Real-time database synchronization enabled
2025-09-24 03:05:02,003 - epetcare - INFO - Database sync manager set up with main DB: C:\epetcare\db.sqlite3, local DB: C:\epetcare\db.sqlite3
2025-09-24 03:05:02,003 - epetcare - INFO - Database sync thread started
2025-09-24 03:05:02,003 - epetcare - INFO - Setting up database connection to C:\epetcare\db.sqlite3
2025-09-24 03:05:02,006 - epetcare - INFO - Database connection established successfully
2025-09-24 03:05:02,006 - epetcare - INFO - Creating main window...
2025-09-24 03:05:05,702 - epetcare - INFO - Application started successfully
2025-09-24 03:05:32,329 - epetcare - INFO - Starting ePetCare Vet Desktop Application
2025-09-24 03:05:32,330 - epetcare - WARNING - Could not import module_finder. Continuing without it.
2025-09-24 03:05:32,527 - epetcare - INFO - Initializing application...
2025-09-24 03:05:32,550 - epetcare - WARNING - Stylesheet not found in any of the checked locations
2025-09-24 03:05:32,551 - epetcare - INFO - Real-time database synchronization enabled
2025-09-24 03:05:32,551 - epetcare - INFO - Database sync manager set up with main DB: C:\epetcare\db.sqlite3, local DB: C:\epetcare\db.sqlite3
2025-09-24 03:05:32,552 - epetcare - INFO - Database sync thread started
2025-09-24 03:05:32,552 - epetcare - INFO - Setting up database connection to C:\epetcare\db.sqlite3
2025-09-24 03:05:32,555 - epetcare - INFO - Database connection established successfully
2025-09-24 03:05:32,555 - epetcare - INFO - Creating main window...
2025-09-24 03:05:35,435 - epetcare - INFO - Application started successfully
2025-09-24 03:13:00,506 - epetcare - INFO - Starting ePetCare Vet Desktop Application
2025-09-24 03:13:00,506 - epetcare - WARNING - Could not import module_finder. Continuing without it.
2025-09-24 03:13:00,695 - epetcare - INFO - Initializing application...
2025-09-24 03:13:00,719 - epetcare - WARNING - Stylesheet not found in any of the checked locations
2025-09-24 03:13:00,719 - epetcare - INFO - Real-time database synchronization enabled
2025-09-24 03:13:00,719 - epetcare - INFO - Database sync manager set up with main DB: C:\epetcare\db.sqlite3, local DB: C:\epetcare\db.sqlite3
2025-09-24 03:13:00,720 - epetcare - INFO - Database sync thread started
2025-09-24 03:13:00,720 - epetcare - INFO - Setting up database connection to C:\epetcare\db.sqlite3
2025-09-24 03:13:00,730 - epetcare - INFO - Database connection established successfully
2025-09-24 03:13:00,730 - epetcare - INFO - Creating main window...
2025-09-24 03:13:05,931 - epetcare - INFO - Application started successfully
2025-09-24 09:50:13,475 - epetcare - INFO - Starting ePetCare Vet Desktop Application
2025-09-24 09:50:13,476 - epetcare - WARNING - Could not import module_finder. Continuing without it.
2025-09-24 09:50:13,904 - epetcare - INFO - Initializing application...
2025-09-24 09:50:13,988 - epetcare - WARNING - Stylesheet not found in any of the checked locations
2025-09-24 09:50:13,988 - epetcare - INFO - Real-time database synchronization enabled
2025-09-24 09:50:13,989 - epetcare - INFO - Database sync manager set up with main DB: C:\epetcare\db.sqlite3, local DB: C:\epetcare\db.sqlite3
2025-09-24 09:50:13,989 - epetcare - INFO - Database sync thread started
2025-09-24 09:50:13,989 - epetcare - INFO - Setting up database connection to C:\epetcare\db.sqlite3
2025-09-24 09:50:14,000 - epetcare - INFO - Database connection established successfully
2025-09-24 09:50:14,000 - epetcare - INFO - Creating main window...
2025-09-24 09:50:18,111 - epetcare - INFO - Application started successfully
2025-09-24 09:50:28,019 - epetcare - INFO - Starting ePetCare Vet Desktop Application
2025-09-24 09:50:28,020 - epetcare - WARNING - Could not import module_finder. Continuing without it.
2025-09-24 09:50:28,219 - epetcare - INFO - Initializing application...
2025-09-24 09:50:28,242 - epetcare - WARNING - Stylesheet not found in any of the checked locations
2025-09-24 09:50:28,243 - epetcare - INFO - Real-time database synchronization enabled
2025-09-24 09:50:28,243 - epetcare - INFO - Database sync manager set up with main DB: C:\epetcare\db.sqlite3, local DB: C:\epetcare\db.sqlite3
2025-09-24 09:50:28,244 - epetcare - INFO - Database sync thread started
2025-09-24 09:50:28,244 - epetcare - INFO - Setting up database connection to C:\epetcare\db.sqlite3
2025-09-24 09:50:28,247 - epetcare - INFO - Database connection established successfully
2025-09-24 09:50:28,247 - epetcare - INFO - Creating main window...
2025-09-24 09:50:34,790 - epetcare - INFO - Application started successfully
2025-09-24 09:55:17,330 - epetcare - INFO - Starting ePetCare Vet Desktop Application
2025-09-24 09:55:17,331 - epetcare - WARNING - Could not import module_finder. Continuing without it.
2025-09-24 09:55:17,531 - epetcare - INFO - Initializing application...
2025-09-24 09:55:17,554 - epetcare - WARNING - Stylesheet not found in any of the checked locations
2025-09-24 09:55:17,555 - epetcare - INFO - Real-time database synchronization enabled
2025-09-24 09:55:17,556 - epetcare - INFO - Database sync manager set up with main DB: C:\epetcare\db.sqlite3, local DB: C:\epetcare\db.sqlite3
2025-09-24 09:55:17,556 - epetcare - INFO - Database sync thread started
2025-09-24 09:55:17,557 - epetcare - INFO - Setting up database connection to C:\epetcare\db.sqlite3
2025-09-24 09:55:17,560 - epetcare - INFO - Database connection established successfully
2025-09-24 09:55:17,560 - epetcare - INFO - Creating main window...
2025-09-24 09:55:21,699 - epetcare - INFO - Application started successfully
2025-09-24 09:55:33,651 - epetcare - INFO - Starting ePetCare Vet Desktop Application
2025-09-24 09:55:33,652 - epetcare - WARNING - Could not import module_finder. Continuing without it.
2025-09-24 09:55:33,847 - epetcare - INFO - Initializing application...
2025-09-24 09:55:33,870 - epetcare - WARNING - Stylesheet not found in any of the checked locations
2025-09-24 09:55:33,871 - epetcare - INFO - Real-time database synchronization enabled
2025-09-24 09:55:33,871 - epetcare - INFO - Database sync manager set up with main DB: C:\epetcare\db.sqlite3, local DB: C:\epetcare\db.sqlite3
2025-09-24 09:55:33,872 - epetcare - INFO - Database sync thread started
2025-09-24 09:55:33,872 - epetcare - INFO - Setting up database connection to C:\epetcare\db.sqlite3
2025-09-24 09:55:33,876 - epetcare - INFO - Database connection established successfully
2025-09-24 09:55:33,876 - epetcare - INFO - Creating main window...
2025-09-24 09:56:25,151 - epetcare - INFO - Starting ePetCare Vet Desktop Application
2025-09-24 09:56:25,151 - epetcare - WARNING - Could not import module_finder. Continuing without it.
2025-09-24 09:56:25,352 - epetcare - INFO - Initializing application...
2025-09-24 09:56:25,380 - epetcare - WARNING - Stylesheet not found in any of the checked locations
2025-09-24 09:56:25,381 - epetcare - INFO - Real-time database synchronization enabled
2025-09-24 09:56:25,381 - epetcare - INFO - Database sync manager set up with main DB: C:\epetcare\db.sqlite3, local DB: C:\epetcare\db.sqlite3
2025-09-24 09:56:25,383 - epetcare - INFO - Database sync thread started
2025-09-24 09:56:25,383 - epetcare - INFO - Setting up database connection to C:\epetcare\db.sqlite3
2025-09-24 09:56:25,394 - epetcare - INFO - Database connection established successfully
2025-09-24 09:56:25,394 - epetcare - INFO - Creating main window...
2025-09-24 09:57:17,734 - epetcare - INFO - Starting ePetCare Vet Desktop Application
2025-09-24 09:57:17,734 - epetcare - WARNING - Could not import module_finder. Continuing without it.
2025-09-24 09:57:17,924 - epetcare - INFO - Initializing application...
2025-09-24 09:57:17,951 - epetcare - WARNING - Stylesheet not found in any of the checked locations
2025-09-24 09:57:17,952 - epetcare - INFO - Real-time database synchronization enabled
2025-09-24 09:57:17,952 - epetcare - INFO - Database sync manager set up with main DB: C:\epetcare\db.sqlite3, local DB: C:\epetcare\db.sqlite3
2025-09-24 09:57:17,953 - epetcare - INFO - Database sync thread started
2025-09-24 09:57:17,953 - epetcare - INFO - Setting up database connection to C:\epetcare\db.sqlite3
2025-09-24 09:57:17,962 - epetcare - INFO - Database connection established successfully
2025-09-24 09:57:17,963 - epetcare - INFO - Creating main window...
2025-09-24 09:59:40,752 - epetcare - INFO - Application started successfully
2025-09-24 10:14:29,240 - epetcare - INFO - Starting ePetCare Vet Desktop Application
2025-09-24 10:14:29,241 - epetcare - WARNING - Could not import module_finder. Continuing without it.
2025-09-24 10:14:29,417 - epetcare - INFO - Initializing application...
2025-09-24 10:14:29,440 - epetcare - WARNING - Stylesheet not found in any of the checked locations
2025-09-24 10:14:29,441 - epetcare - INFO - Real-time database synchronization enabled
2025-09-24 10:14:29,441 - epetcare - INFO - Database sync manager set up with main DB: C:\epetcare\db.sqlite3, local DB: C:\epetcare\db.sqlite3
2025-09-24 10:14:29,442 - epetcare - INFO - Database sync thread started
2025-09-24 10:14:29,442 - epetcare - INFO - Setting up database connection to C:\epetcare\db.sqlite3
2025-09-24 10:14:29,446 - epetcare - INFO - Database connection established successfully
2025-09-24 10:14:29,446 - epetcare - INFO - Creating main window...
2025-09-24 10:14:37,272 - epetcare - INFO - Application started successfully
2025-09-24 10:15:56,966 - epetcare - INFO - Starting ePetCare Vet Desktop Application
2025-09-24 10:15:56,967 - epetcare - WARNING - Could not import module_finder. Continuing without it.
2025-09-24 10:15:57,161 - epetcare - INFO - Initializing application...
2025-09-24 10:15:57,185 - epetcare - WARNING - Stylesheet not found in any of the checked locations
2025-09-24 10:15:57,185 - epetcare - INFO - Real-time database synchronization enabled
2025-09-24 10:15:57,186 - epetcare - INFO - Database sync manager set up with main DB: C:\epetcare\db.sqlite3, local DB: C:\epetcare\db.sqlite3
2025-09-24 10:15:57,186 - epetcare - INFO - Database sync thread started
2025-09-24 10:15:57,187 - epetcare - INFO - Setting up database connection to C:\epetcare\db.sqlite3
2025-09-24 10:15:57,189 - epetcare - INFO - Database connection established successfully
2025-09-24 10:15:57,189 - epetcare - INFO - Creating main window...
2025-09-24 10:16:00,956 - epetcare - INFO - Application started successfully
2025-09-24 10:17:40,529 - epetcare - INFO - Starting ePetCare Vet Desktop Application
2025-09-24 10:17:40,530 - epetcare - WARNING - Could not import module_finder. Continuing without it.
2025-09-24 10:17:40,792 - epetcare - INFO - Initializing application...
2025-09-24 10:17:40,821 - epetcare - INFO - Real-time database synchronization enabled
2025-09-24 10:17:40,822 - epetcare - INFO - Database sync manager set up with main DB: C:\epetcare\db.sqlite3, local DB: C:\epetcare\db.sqlite3
2025-09-24 10:17:40,822 - epetcare - INFO - Database sync thread started
2025-09-24 10:17:40,823 - epetcare - INFO - Setting up database connection to C:\epetcare\db.sqlite3
2025-09-24 10:17:40,835 - epetcare - INFO - Database connection established successfully
2025-09-24 10:17:40,835 - epetcare - INFO - Creating main window...
2025-09-24 10:17:46,893 - epetcare - INFO - Application started successfully
2025-09-24 10:20:41,933 - epetcare - INFO - Starting ePetCare Vet Desktop Application
2025-09-24 10:20:41,934 - epetcare - WARNING - Could not import module_finder. Continuing without it.
2025-09-24 10:20:42,132 - epetcare - INFO - Initializing application...
2025-09-24 10:20:42,155 - epetcare - WARNING - Stylesheet not found in any of the checked locations
2025-09-24 10:20:42,156 - epetcare - INFO - Real-time database synchronization enabled
2025-09-24 10:20:42,156 - epetcare - INFO - Database sync manager set up with main DB: C:\epetcare\db.sqlite3, local DB: C:\epetcare\db.sqlite3
2025-09-24 10:20:42,157 - epetcare - INFO - Database sync thread started
2025-09-24 10:20:42,157 - epetcare - INFO - Setting up database connection to C:\epetcare\db.sqlite3
2025-09-24 10:20:42,160 - epetcare - INFO - Database connection established successfully
2025-09-24 10:20:42,160 - epetcare - INFO - Creating main window...
2025-09-24 10:20:46,711 - epetcare - INFO - Application started successfully
2025-09-24 10:29:12,805 - epetcare - INFO - Starting ePetCare Vet Desktop Application
2025-09-24 10:29:12,807 - epetcare - WARNING - Could not import module_finder. Continuing without it.
2025-09-24 10:29:13,068 - epetcare - INFO - Initializing application...
2025-09-24 10:29:13,096 - epetcare - INFO - Real-time database synchronization enabled
2025-09-24 10:29:13,097 - epetcare - INFO - Database sync manager set up with main DB: C:\epetcare\db.sqlite3, local DB: C:\epetcare\db.sqlite3
2025-09-24 10:29:13,097 - epetcare - INFO - Database sync thread started
2025-09-24 10:29:13,097 - epetcare - INFO - Setting up database connection to C:\epetcare\db.sqlite3
2025-09-24 10:29:13,100 - epetcare - INFO - Database connection established successfully
2025-09-24 10:29:13,100 - epetcare - INFO - Creating main window...
2025-09-24 10:29:48,737 - epetcare - INFO - Application started successfully
2025-09-24 10:30:11,549 - epetcare - INFO - Starting ePetCare Vet Desktop Application
2025-09-24 10:30:11,550 - epetcare - WARNING - Could not import module_finder. Continuing without it.
2025-09-24 10:30:11,780 - epetcare - INFO - Initializing application...
2025-09-24 10:30:11,808 - epetcare - WARNING - Stylesheet not found in any of the checked locations
2025-09-24 10:30:11,809 - epetcare - INFO - Real-time database synchronization enabled
2025-09-24 10:30:11,809 - epetcare - INFO - Database sync manager set up with main DB: C:\epetcare\db.sqlite3, local DB: C:\epetcare\db.sqlite3
2025-09-24 10:30:11,809 - epetcare - INFO - Database sync thread started
2025-09-24 10:30:11,810 - epetcare - INFO - Setting up database connection to C:\epetcare\db.sqlite3
2025-09-24 10:30:11,813 - epetcare - INFO - Database connection established successfully
2025-09-24 10:30:11,814 - epetcare - INFO - Creating main window...
2025-09-24 10:30:16,197 - epetcare - INFO - Application started successfully
2025-09-25 03:08:35,625 - epetcare - INFO - Starting ePetCare Vet Desktop Application
2025-09-25 03:08:35,626 - epetcare - WARNING - Could not import module_finder. Continuing without it.
2025-09-25 03:08:35,985 - epetcare - INFO - Initializing application...
2025-09-25 03:08:36,070 - epetcare - WARNING - Stylesheet not found in any of the checked locations
2025-09-25 03:08:36,071 - epetcare - INFO - Real-time database synchronization enabled
2025-09-25 03:08:36,071 - epetcare - INFO - Database sync manager set up with main DB: C:\epetcare\db.sqlite3, local DB: C:\epetcare\db.sqlite3
2025-09-25 03:08:36,071 - epetcare - INFO - Database sync thread started
2025-09-25 03:08:36,071 - epetcare - INFO - Setting up database connection to C:\epetcare\db.sqlite3
2025-09-25 03:08:36,074 - epetcare - INFO - Database connection established successfully
2025-09-25 03:08:36,075 - epetcare - INFO - Creating main window...
2025-09-25 03:08:41,842 - epetcare - INFO - Application started successfully
2025-09-26 00:49:39,116 - epetcare - INFO - Starting ePetCare Vet Desktop Application
2025-09-26 00:49:39,117 - epetcare - WARNING - Could not import module_finder. Continuing without it.
2025-09-26 00:49:39,655 - epetcare - INFO - Initializing application...
2025-09-26 00:49:39,742 - epetcare - WARNING - Stylesheet not found in any of the checked locations
2025-09-26 00:49:39,743 - epetcare - INFO - Real-time database synchronization enabled
2025-09-26 00:49:39,743 - epetcare - INFO - Database sync manager set up with main DB: C:\epetcare\db.sqlite3, local DB: C:\epetcare\db.sqlite3
2025-09-26 00:49:39,743 - epetcare - INFO - Database sync thread started
2025-09-26 00:49:39,743 - epetcare - INFO - Setting up database connection to C:\epetcare\db.sqlite3
2025-09-26 00:49:39,748 - epetcare - INFO - Database connection established successfully
2025-09-26 00:49:39,748 - epetcare - INFO - Creating main window...
2025-09-26 00:49:43,225 - epetcare - INFO - Application started successfully
2025-09-26 01:07:37,803 - epetcare - INFO - Starting ePetCare Vet Desktop Application
2025-09-26 01:07:37,804 - epetcare - WARNING - Could not import module_finder. Continuing without it.
2025-09-26 01:07:38,176 - epetcare - INFO - Initializing application...
2025-09-26 01:07:38,201 - epetcare - WARNING - Stylesheet not found in any of the checked locations
2025-09-26 01:07:38,202 - epetcare - INFO - Remote database is enabled with URL: https://epetcare.onrender.com/vet_portal/api
2025-09-26 01:07:38,202 - epetcare - INFO - Remote database is enabled with URL: https://epetcare.onrender.com/vet_portal/api
2025-09-26 01:07:38,215 - epetcare - INFO - Network database manager set up with remote URL: https://epetcare.onrender.com/vet_portal/api
2025-09-26 01:07:38,215 - epetcare - INFO - Detected Render-deployed application, using API endpoints
2025-09-26 01:07:38,217 - epetcare - INFO - Setting up remote database client for https://epetcare.onrender.com/vet_portal/api
2025-09-26 01:07:39,580 - epetcare - ERROR - Authentication failed: 404 - 
<!doctype html>
<html lang="en">
<head>
  <title>Not Found</title>
</head>
<body>
  <h1>Not Found</h1><p>The requested resource was not found on this server.</p>
</body>
</html>

2025-09-26 01:07:39,581 - epetcare - ERROR - Failed to set up remote database client
2025-09-26 01:07:39,582 - epetcare - ERROR - Failed to set up remote database connection
2025-09-26 01:07:39,583 - epetcare - INFO - Database sync manager set up with main DB: C:\epetcare\db.sqlite3, local DB: C:\epetcare\data\db.sqlite3
2025-09-26 01:07:39,583 - epetcare - INFO - Creating local database from main database
2025-09-26 01:07:39,585 - epetcare - INFO - Local database created successfully
2025-09-26 01:07:39,585 - epetcare - INFO - Remote database sync configured with interval: 30 seconds
2025-09-26 01:07:39,586 - epetcare - INFO - Database sync thread started
2025-09-26 01:07:39,586 - epetcare - INFO - Setting up database connection to C:\epetcare\data\db.sqlite3
2025-09-26 01:07:39,587 - epetcare - INFO - Syncing database from C:\epetcare\db.sqlite3 to C:\epetcare\data\db.sqlite3
2025-09-26 01:07:39,591 - epetcare - INFO - Database connection established successfully
2025-09-26 01:07:39,591 - epetcare - INFO - Creating main window...
2025-09-26 01:07:53,669 - epetcare - INFO - Application started successfully
2025-09-26 01:08:36,319 - epetcare - INFO - Starting ePetCare Vet Desktop Application
2025-09-26 01:08:36,320 - epetcare - WARNING - Could not import module_finder. Continuing without it.
2025-09-26 01:08:36,635 - epetcare - INFO - Initializing application...
2025-09-26 01:08:36,660 - epetcare - WARNING - Stylesheet not found in any of the checked locations
2025-09-26 01:08:36,661 - epetcare - INFO - Remote database is enabled with URL: https://epetcare.onrender.com/vet_portal/api
2025-09-26 01:08:36,661 - epetcare - INFO - Remote database is enabled with URL: https://epetcare.onrender.com/vet_portal/api
2025-09-26 01:08:36,662 - epetcare - INFO - Network database manager set up with remote URL: https://epetcare.onrender.com/vet_portal/api
2025-09-26 01:08:36,662 - epetcare - INFO - Detected Render-deployed application, using API endpoints
2025-09-26 01:08:36,663 - epetcare - INFO - Setting up remote database client for https://epetcare.onrender.com/vet_portal/api
2025-09-26 01:08:37,452 - epetcare - ERROR - Authentication failed: 404 - 
<!doctype html>
<html lang="en">
<head>
  <title>Not Found</title>
</head>
<body>
  <h1>Not Found</h1><p>The requested resource was not found on this server.</p>
</body>
</html>

2025-09-26 01:08:37,453 - epetcare - ERROR - Failed to set up remote database client
2025-09-26 01:08:37,454 - epetcare - ERROR - Failed to set up remote database connection
2025-09-26 01:08:37,454 - epetcare - INFO - Database sync manager set up with main DB: C:\epetcare\db.sqlite3, local DB: C:\epetcare\data\db.sqlite3
2025-09-26 01:08:37,455 - epetcare - INFO - Remote database sync configured with interval: 30 seconds
2025-09-26 01:08:37,456 - epetcare - INFO - Database sync thread started
2025-09-26 01:08:37,456 - epetcare - INFO - Setting up database connection to C:\epetcare\data\db.sqlite3
2025-09-26 01:08:37,456 - epetcare - INFO - Syncing database from C:\epetcare\db.sqlite3 to C:\epetcare\data\db.sqlite3
2025-09-26 01:08:37,460 - epetcare - WARNING - Failed to set PRAGMA settings: database disk image is malformed
2025-09-26 01:08:37,460 - epetcare - ERROR - SQLite error: database disk image is malformed
2025-09-26 01:08:37,500 - epetcare - ERROR - Traceback (most recent call last):
  File "C:\epetcare\vet_desktop_app\utils\database.py", line 138, in setup_database_connection
    cursor.execute("SELECT name FROM sqlite_master WHERE type='table'")
    ~~~~~~~~~~~~~~^^^^^^^^^^^^^^^^^^^^^^^^^^^^^^^^^^^^^^^^^^^^^^^^^^^^^
sqlite3.DatabaseError: database disk image is malformed

2025-09-26 01:08:41,932 - epetcare - ERROR - Failed to connect to database
2025-09-26 01:25:12,166 - epetcare - INFO - Starting ePetCare Vet Desktop Application
2025-09-26 01:25:12,167 - epetcare - WARNING - Could not import module_finder. Continuing without it.
2025-09-26 01:25:12,532 - epetcare - INFO - Initializing application...
2025-09-26 01:25:12,555 - epetcare - WARNING - Stylesheet not found in any of the checked locations
2025-09-26 01:25:12,555 - epetcare - INFO - Remote database is enabled with URL: https://epetcare.onrender.com
2025-09-26 01:25:12,556 - epetcare - INFO - Remote database is enabled with URL: https://epetcare.onrender.com
2025-09-26 01:25:12,557 - epetcare - INFO - Network database manager set up with remote URL: https://epetcare.onrender.com
2025-09-26 01:25:12,557 - epetcare - INFO - Detected Render-deployed application, using API endpoints
2025-09-26 01:25:12,558 - epetcare - INFO - Setting up remote database client for https://epetcare.onrender.com
2025-09-26 01:25:18,831 - epetcare - ERROR - All authentication attempts failed
2025-09-26 01:25:18,831 - epetcare - WARNING - Falling back to anonymous access
2025-09-26 01:25:18,833 - epetcare - INFO - Syncing database from https://epetcare.onrender.com using API
2025-09-26 01:25:23,496 - epetcare - ERROR - All attempts to download database failed
2025-09-26 01:25:23,496 - epetcare - WARNING - Creating a new empty database as fallback
2025-09-26 01:25:23,554 - epetcare - INFO - Database synced successfully to C:\Users\Shiro\AppData\Local\Temp\epetcare_t5ejlbfe.sqlite3
2025-09-26 01:25:23,555 - epetcare - INFO - Using remote database at C:\Users\Shiro\AppData\Local\Temp\epetcare_t5ejlbfe.sqlite3
2025-09-26 01:25:23,556 - epetcare - INFO - Database sync manager set up with main DB: C:\Users\Shiro\AppData\Local\Temp\epetcare_t5ejlbfe.sqlite3, local DB: C:\epetcare\data\db.sqlite3
2025-09-26 01:25:23,556 - epetcare - INFO - Remote database sync configured with interval: 30 seconds
2025-09-26 01:25:23,557 - epetcare - INFO - Database sync thread started
2025-09-26 01:25:23,557 - epetcare - INFO - Syncing with remote database
2025-09-26 01:25:23,557 - epetcare - INFO - Setting up database connection to C:\epetcare\data\db.sqlite3
2025-09-26 01:25:23,558 - epetcare - INFO - Syncing database from https://epetcare.onrender.com using API
2025-09-26 01:25:23,562 - epetcare - INFO - Database connection established successfully
2025-09-26 01:25:23,562 - epetcare - INFO - Creating main window...
2025-09-26 01:25:28,595 - epetcare - ERROR - All attempts to download database failed
2025-09-26 01:25:28,596 - epetcare - WARNING - Creating a new empty database as fallback
2025-09-26 01:25:28,601 - epetcare - INFO - Database synced successfully to C:\Users\Shiro\AppData\Local\Temp\epetcare_t5ejlbfe.sqlite3
2025-09-26 01:25:34,510 - epetcare - INFO - Application started successfully
2025-09-26 01:25:58,601 - epetcare - INFO - Syncing with remote database
2025-09-26 01:25:58,601 - epetcare - INFO - Syncing database from https://epetcare.onrender.com using API
2025-09-26 01:26:03,403 - epetcare - ERROR - All attempts to download database failed
2025-09-26 01:26:03,406 - epetcare - WARNING - Creating a new empty database as fallback
2025-09-26 01:26:03,409 - epetcare - INFO - Database synced successfully to C:\Users\Shiro\AppData\Local\Temp\epetcare_t5ejlbfe.sqlite3
2025-09-26 01:26:33,406 - epetcare - INFO - Syncing with remote database
2025-09-26 01:26:33,406 - epetcare - INFO - Syncing database from https://epetcare.onrender.com using API
2025-09-26 01:26:37,723 - epetcare - ERROR - All attempts to download database failed
2025-09-26 01:26:37,726 - epetcare - WARNING - Creating a new empty database as fallback
2025-09-26 01:26:37,729 - epetcare - INFO - Database synced successfully to C:\Users\Shiro\AppData\Local\Temp\epetcare_t5ejlbfe.sqlite3
2025-09-26 01:27:07,727 - epetcare - INFO - Syncing with remote database
2025-09-26 01:27:07,727 - epetcare - INFO - Syncing database from https://epetcare.onrender.com using API
2025-09-26 01:27:12,452 - epetcare - ERROR - All attempts to download database failed
2025-09-26 01:27:12,452 - epetcare - WARNING - Creating a new empty database as fallback
2025-09-26 01:27:12,456 - epetcare - INFO - Database synced successfully to C:\Users\Shiro\AppData\Local\Temp\epetcare_t5ejlbfe.sqlite3
2025-09-26 01:27:42,459 - epetcare - INFO - Syncing with remote database
2025-09-26 01:27:42,460 - epetcare - INFO - Syncing database from https://epetcare.onrender.com using API
2025-09-26 01:27:46,732 - epetcare - ERROR - All attempts to download database failed
2025-09-26 01:27:46,733 - epetcare - WARNING - Creating a new empty database as fallback
2025-09-26 01:27:46,737 - epetcare - INFO - Database synced successfully to C:\Users\Shiro\AppData\Local\Temp\epetcare_t5ejlbfe.sqlite3
2025-09-26 01:28:16,740 - epetcare - INFO - Syncing with remote database
2025-09-26 01:28:16,740 - epetcare - INFO - Syncing database from https://epetcare.onrender.com using API
2025-09-26 01:28:21,503 - epetcare - ERROR - All attempts to download database failed
2025-09-26 01:28:21,503 - epetcare - WARNING - Creating a new empty database as fallback
2025-09-26 01:28:21,506 - epetcare - INFO - Database synced successfully to C:\Users\Shiro\AppData\Local\Temp\epetcare_t5ejlbfe.sqlite3
2025-09-26 01:28:51,508 - epetcare - INFO - Syncing with remote database
2025-09-26 01:28:51,508 - epetcare - INFO - Syncing database from https://epetcare.onrender.com using API
2025-09-26 01:28:55,881 - epetcare - ERROR - All attempts to download database failed
2025-09-26 01:28:55,881 - epetcare - WARNING - Creating a new empty database as fallback
2025-09-26 01:28:55,885 - epetcare - INFO - Database synced successfully to C:\Users\Shiro\AppData\Local\Temp\epetcare_t5ejlbfe.sqlite3
2025-09-26 01:29:25,882 - epetcare - INFO - Syncing with remote database
2025-09-26 01:29:25,883 - epetcare - INFO - Syncing database from https://epetcare.onrender.com using API
2025-09-26 01:29:29,901 - epetcare - ERROR - All attempts to download database failed
2025-09-26 01:29:29,901 - epetcare - WARNING - Creating a new empty database as fallback
2025-09-26 01:29:29,904 - epetcare - INFO - Database synced successfully to C:\Users\Shiro\AppData\Local\Temp\epetcare_t5ejlbfe.sqlite3
2025-09-26 01:29:59,905 - epetcare - INFO - Syncing with remote database
2025-09-26 01:29:59,906 - epetcare - INFO - Syncing database from https://epetcare.onrender.com using API
2025-09-26 01:30:04,321 - epetcare - ERROR - All attempts to download database failed
2025-09-26 01:30:04,322 - epetcare - WARNING - Creating a new empty database as fallback
2025-09-26 01:30:04,328 - epetcare - INFO - Database synced successfully to C:\Users\Shiro\AppData\Local\Temp\epetcare_t5ejlbfe.sqlite3
2025-09-26 01:30:34,325 - epetcare - INFO - Syncing with remote database
2025-09-26 01:30:34,325 - epetcare - INFO - Syncing database from https://epetcare.onrender.com using API
2025-09-26 01:30:39,412 - epetcare - ERROR - All attempts to download database failed
2025-09-26 01:30:39,413 - epetcare - WARNING - Creating a new empty database as fallback
2025-09-26 01:30:39,416 - epetcare - INFO - Database synced successfully to C:\Users\Shiro\AppData\Local\Temp\epetcare_t5ejlbfe.sqlite3
2025-09-26 01:31:09,416 - epetcare - INFO - Syncing with remote database
2025-09-26 01:31:09,417 - epetcare - INFO - Syncing database from https://epetcare.onrender.com using API
2025-09-26 01:31:14,219 - epetcare - ERROR - All attempts to download database failed
2025-09-26 01:31:14,219 - epetcare - WARNING - Creating a new empty database as fallback
2025-09-26 01:31:14,222 - epetcare - INFO - Database synced successfully to C:\Users\Shiro\AppData\Local\Temp\epetcare_t5ejlbfe.sqlite3
2025-09-26 01:31:44,235 - epetcare - INFO - Syncing with remote database
2025-09-26 01:31:44,235 - epetcare - INFO - Syncing database from https://epetcare.onrender.com using API
2025-09-26 01:31:48,707 - epetcare - ERROR - All attempts to download database failed
2025-09-26 01:31:48,707 - epetcare - WARNING - Creating a new empty database as fallback
2025-09-26 01:31:48,711 - epetcare - INFO - Database synced successfully to C:\Users\Shiro\AppData\Local\Temp\epetcare_t5ejlbfe.sqlite3
2025-09-26 01:32:18,717 - epetcare - INFO - Syncing with remote database
2025-09-26 01:32:18,717 - epetcare - INFO - Syncing database from https://epetcare.onrender.com using API
2025-09-26 01:32:23,507 - epetcare - ERROR - All attempts to download database failed
2025-09-26 01:32:23,508 - epetcare - WARNING - Creating a new empty database as fallback
2025-09-26 01:32:23,511 - epetcare - INFO - Database synced successfully to C:\Users\Shiro\AppData\Local\Temp\epetcare_t5ejlbfe.sqlite3
2025-09-26 01:32:53,500 - epetcare - INFO - Syncing with remote database
2025-09-26 01:32:53,500 - epetcare - INFO - Syncing database from https://epetcare.onrender.com using API
2025-09-26 01:32:59,093 - epetcare - ERROR - All attempts to download database failed
2025-09-26 01:32:59,093 - epetcare - WARNING - Creating a new empty database as fallback
2025-09-26 01:32:59,096 - epetcare - INFO - Database synced successfully to C:\Users\Shiro\AppData\Local\Temp\epetcare_t5ejlbfe.sqlite3
2025-09-26 01:33:29,097 - epetcare - INFO - Syncing with remote database
2025-09-26 01:33:29,097 - epetcare - INFO - Syncing database from https://epetcare.onrender.com using API
2025-09-26 01:33:34,545 - epetcare - ERROR - All attempts to download database failed
2025-09-26 01:33:34,546 - epetcare - WARNING - Creating a new empty database as fallback
2025-09-26 01:33:34,550 - epetcare - INFO - Database synced successfully to C:\Users\Shiro\AppData\Local\Temp\epetcare_t5ejlbfe.sqlite3
2025-09-26 01:34:04,561 - epetcare - INFO - Syncing with remote database
2025-09-26 01:34:04,561 - epetcare - INFO - Syncing database from https://epetcare.onrender.com using API
2025-09-26 01:34:08,907 - epetcare - ERROR - All attempts to download database failed
2025-09-26 01:34:08,911 - epetcare - WARNING - Creating a new empty database as fallback
2025-09-26 01:34:08,914 - epetcare - INFO - Database synced successfully to C:\Users\Shiro\AppData\Local\Temp\epetcare_t5ejlbfe.sqlite3
2025-09-26 01:34:38,906 - epetcare - INFO - Syncing with remote database
2025-09-26 01:34:38,906 - epetcare - INFO - Syncing database from https://epetcare.onrender.com using API
2025-09-26 01:34:43,790 - epetcare - ERROR - All attempts to download database failed
2025-09-26 01:34:43,792 - epetcare - WARNING - Creating a new empty database as fallback
2025-09-26 01:34:43,794 - epetcare - INFO - Database synced successfully to C:\Users\Shiro\AppData\Local\Temp\epetcare_t5ejlbfe.sqlite3
2025-09-26 01:35:13,790 - epetcare - INFO - Syncing with remote database
2025-09-26 01:35:13,791 - epetcare - INFO - Syncing database from https://epetcare.onrender.com using API
2025-09-26 01:35:18,927 - epetcare - ERROR - All attempts to download database failed
2025-09-26 01:35:18,929 - epetcare - WARNING - Creating a new empty database as fallback
2025-09-26 01:35:18,931 - epetcare - INFO - Database synced successfully to C:\Users\Shiro\AppData\Local\Temp\epetcare_t5ejlbfe.sqlite3
2025-09-26 01:35:48,921 - epetcare - INFO - Syncing with remote database
2025-09-26 01:35:48,921 - epetcare - INFO - Syncing database from https://epetcare.onrender.com using API
2025-09-26 01:35:53,380 - epetcare - ERROR - All attempts to download database failed
2025-09-26 01:35:53,381 - epetcare - WARNING - Creating a new empty database as fallback
2025-09-26 01:35:53,384 - epetcare - INFO - Database synced successfully to C:\Users\Shiro\AppData\Local\Temp\epetcare_t5ejlbfe.sqlite3
2025-09-26 01:36:23,376 - epetcare - INFO - Syncing with remote database
2025-09-26 01:36:23,376 - epetcare - INFO - Syncing database from https://epetcare.onrender.com using API
2025-09-26 01:36:28,470 - epetcare - ERROR - All attempts to download database failed
2025-09-26 01:36:28,471 - epetcare - WARNING - Creating a new empty database as fallback
2025-09-26 01:36:28,474 - epetcare - INFO - Database synced successfully to C:\Users\Shiro\AppData\Local\Temp\epetcare_t5ejlbfe.sqlite3
2025-09-26 01:36:58,475 - epetcare - INFO - Syncing with remote database
2025-09-26 01:36:58,475 - epetcare - INFO - Syncing database from https://epetcare.onrender.com using API
2025-09-26 01:37:02,688 - epetcare - ERROR - All attempts to download database failed
2025-09-26 01:37:02,689 - epetcare - WARNING - Creating a new empty database as fallback
2025-09-26 01:37:02,691 - epetcare - INFO - Database synced successfully to C:\Users\Shiro\AppData\Local\Temp\epetcare_t5ejlbfe.sqlite3
2025-09-26 01:37:32,694 - epetcare - INFO - Syncing with remote database
2025-09-26 01:37:32,694 - epetcare - INFO - Syncing database from https://epetcare.onrender.com using API
2025-09-26 01:37:37,790 - epetcare - ERROR - All attempts to download database failed
2025-09-26 01:37:37,791 - epetcare - WARNING - Creating a new empty database as fallback
2025-09-26 01:37:37,794 - epetcare - INFO - Database synced successfully to C:\Users\Shiro\AppData\Local\Temp\epetcare_t5ejlbfe.sqlite3
2025-09-26 01:38:07,795 - epetcare - INFO - Syncing with remote database
2025-09-26 01:38:07,795 - epetcare - INFO - Syncing database from https://epetcare.onrender.com using API
2025-09-26 01:38:12,424 - epetcare - ERROR - All attempts to download database failed
2025-09-26 01:38:12,425 - epetcare - WARNING - Creating a new empty database as fallback
2025-09-26 01:38:12,428 - epetcare - INFO - Database synced successfully to C:\Users\Shiro\AppData\Local\Temp\epetcare_t5ejlbfe.sqlite3
2025-09-26 01:38:42,428 - epetcare - INFO - Syncing with remote database
2025-09-26 01:38:42,429 - epetcare - INFO - Syncing database from https://epetcare.onrender.com using API
2025-09-26 01:38:47,089 - epetcare - ERROR - All attempts to download database failed
2025-09-26 01:38:47,090 - epetcare - WARNING - Creating a new empty database as fallback
2025-09-26 01:38:47,093 - epetcare - INFO - Database synced successfully to C:\Users\Shiro\AppData\Local\Temp\epetcare_t5ejlbfe.sqlite3
2025-09-26 01:39:17,096 - epetcare - INFO - Syncing with remote database
2025-09-26 01:39:17,096 - epetcare - INFO - Syncing database from https://epetcare.onrender.com using API
2025-09-26 01:39:22,330 - epetcare - ERROR - All attempts to download database failed
2025-09-26 01:39:22,330 - epetcare - WARNING - Creating a new empty database as fallback
2025-09-26 01:39:22,334 - epetcare - INFO - Database synced successfully to C:\Users\Shiro\AppData\Local\Temp\epetcare_t5ejlbfe.sqlite3
2025-09-26 01:40:29,957 - epetcare - INFO - Starting ePetCare Vet Desktop Application
2025-09-26 01:40:29,958 - epetcare - WARNING - Could not import module_finder. Continuing without it.
2025-09-26 01:40:30,279 - epetcare - INFO - Initializing application...
2025-09-26 01:40:30,301 - epetcare - WARNING - Stylesheet not found in any of the checked locations
2025-09-26 01:40:30,302 - epetcare - INFO - Remote database is enabled with URL: https://epetcare.onrender.com
2025-09-26 01:40:30,303 - epetcare - INFO - Remote database is enabled with URL: https://epetcare.onrender.com
2025-09-26 01:40:30,304 - epetcare - INFO - Network database manager set up with remote URL: https://epetcare.onrender.com
2025-09-26 01:40:30,304 - epetcare - INFO - Detected Render-deployed application, using API endpoints
2025-09-26 01:40:30,305 - epetcare - INFO - Setting up remote database client for https://epetcare.onrender.com
2025-09-26 01:40:32,164 - epetcare - ERROR - All authentication attempts failed
2025-09-26 01:40:32,165 - epetcare - WARNING - Falling back to anonymous access
2025-09-26 01:40:32,165 - epetcare - INFO - Syncing database from https://epetcare.onrender.com using API
2025-09-26 01:40:35,388 - epetcare - ERROR - All attempts to download database failed
2025-09-26 01:40:35,388 - epetcare - WARNING - Creating a new empty database as fallback
2025-09-26 01:40:35,434 - epetcare - INFO - Database synced successfully to C:\Users\Shiro\AppData\Local\Temp\epetcare_ov8g8q_d.sqlite3
2025-09-26 01:40:35,434 - epetcare - INFO - Using remote database at C:\Users\Shiro\AppData\Local\Temp\epetcare_ov8g8q_d.sqlite3
2025-09-26 01:40:35,435 - epetcare - INFO - Database sync manager set up with main DB: C:\Users\Shiro\AppData\Local\Temp\epetcare_ov8g8q_d.sqlite3, local DB: C:\epetcare\data\db.sqlite3
2025-09-26 01:40:35,436 - epetcare - INFO - Remote database sync configured with interval: 30 seconds
2025-09-26 01:40:35,436 - epetcare - INFO - Database sync thread started
2025-09-26 01:40:35,436 - epetcare - INFO - Syncing with remote database
2025-09-26 01:40:35,436 - epetcare - INFO - Setting up database connection to C:\epetcare\data\db.sqlite3
2025-09-26 01:40:35,437 - epetcare - INFO - Syncing database from https://epetcare.onrender.com using API
2025-09-26 01:40:35,449 - epetcare - INFO - Database connection established successfully
2025-09-26 01:40:35,449 - epetcare - INFO - Creating main window...
2025-09-26 01:40:39,822 - epetcare - ERROR - All attempts to download database failed
2025-09-26 01:40:39,823 - epetcare - WARNING - Creating a new empty database as fallback
2025-09-26 01:40:39,828 - epetcare - INFO - Database synced successfully to C:\Users\Shiro\AppData\Local\Temp\epetcare_ov8g8q_d.sqlite3
2025-09-26 01:40:42,257 - epetcare - INFO - Application started successfully
2025-09-26 01:41:09,836 - epetcare - INFO - Syncing with remote database
2025-09-26 01:41:09,836 - epetcare - INFO - Syncing database from https://epetcare.onrender.com using API
2025-09-26 01:41:14,496 - epetcare - ERROR - All attempts to download database failed
2025-09-26 01:41:14,497 - epetcare - WARNING - Creating a new empty database as fallback
2025-09-26 01:41:14,500 - epetcare - INFO - Database synced successfully to C:\Users\Shiro\AppData\Local\Temp\epetcare_ov8g8q_d.sqlite3
2025-09-26 01:41:44,502 - epetcare - INFO - Syncing with remote database
2025-09-26 01:41:44,502 - epetcare - INFO - Syncing database from https://epetcare.onrender.com using API
2025-09-26 01:41:49,019 - epetcare - ERROR - All attempts to download database failed
2025-09-26 01:41:49,020 - epetcare - WARNING - Creating a new empty database as fallback
2025-09-26 01:41:49,023 - epetcare - INFO - Database synced successfully to C:\Users\Shiro\AppData\Local\Temp\epetcare_ov8g8q_d.sqlite3
2025-09-26 01:42:25,301 - epetcare - INFO - Starting ePetCare Vet Desktop Application
2025-09-26 01:42:25,302 - epetcare - WARNING - Could not import module_finder. Continuing without it.
2025-09-26 01:42:25,625 - epetcare - INFO - Initializing application...
2025-09-26 01:42:25,649 - epetcare - WARNING - Stylesheet not found in any of the checked locations
2025-09-26 01:42:25,650 - epetcare - INFO - Remote database is enabled with URL: https://epetcare.onrender.com
2025-09-26 01:42:25,650 - epetcare - INFO - Remote database is enabled with URL: https://epetcare.onrender.com
2025-09-26 01:42:25,652 - epetcare - INFO - Network database manager set up with remote URL: https://epetcare.onrender.com
2025-09-26 01:42:25,652 - epetcare - INFO - Detected Render-deployed application, using API endpoints
2025-09-26 01:42:25,653 - epetcare - INFO - Setting up remote database client for https://epetcare.onrender.com
2025-09-26 01:42:27,948 - epetcare - ERROR - All authentication attempts failed
2025-09-26 01:42:27,948 - epetcare - WARNING - Falling back to anonymous access
2025-09-26 01:42:27,950 - epetcare - INFO - Syncing database from https://epetcare.onrender.com using API
2025-09-26 01:42:31,690 - epetcare - ERROR - All attempts to download database failed
2025-09-26 01:42:31,691 - epetcare - WARNING - Creating a new empty database as fallback
2025-09-26 01:42:31,733 - epetcare - INFO - Database synced successfully to C:\Users\Shiro\AppData\Local\Temp\epetcare_u2iroxjt.sqlite3
2025-09-26 01:42:31,733 - epetcare - INFO - Using remote database at C:\Users\Shiro\AppData\Local\Temp\epetcare_u2iroxjt.sqlite3
2025-09-26 01:42:31,734 - epetcare - INFO - Database sync manager set up with main DB: C:\Users\Shiro\AppData\Local\Temp\epetcare_u2iroxjt.sqlite3, local DB: C:\epetcare\data\db.sqlite3
2025-09-26 01:42:31,735 - epetcare - INFO - Remote database sync configured with interval: 30 seconds
2025-09-26 01:42:31,736 - epetcare - INFO - Database sync thread started
2025-09-26 01:42:31,736 - epetcare - INFO - Syncing with remote database
2025-09-26 01:42:31,736 - epetcare - INFO - Setting up database connection to C:\epetcare\data\db.sqlite3
2025-09-26 01:42:31,736 - epetcare - INFO - Syncing database from https://epetcare.onrender.com using API
2025-09-26 01:42:31,740 - epetcare - INFO - Database connection established successfully
2025-09-26 01:42:31,740 - epetcare - INFO - Creating main window...
2025-09-26 01:42:36,004 - epetcare - ERROR - All attempts to download database failed
2025-09-26 01:42:36,005 - epetcare - WARNING - Creating a new empty database as fallback
2025-09-26 01:42:36,010 - epetcare - INFO - Database synced successfully to C:\Users\Shiro\AppData\Local\Temp\epetcare_u2iroxjt.sqlite3
2025-09-26 01:42:40,582 - epetcare - INFO - Application started successfully
2025-09-26 01:43:06,022 - epetcare - INFO - Syncing with remote database
2025-09-26 01:43:06,022 - epetcare - INFO - Syncing database from https://epetcare.onrender.com using API
2025-09-26 01:43:10,214 - epetcare - ERROR - All attempts to download database failed
2025-09-26 01:43:10,215 - epetcare - WARNING - Creating a new empty database as fallback
2025-09-26 01:43:10,218 - epetcare - INFO - Database synced successfully to C:\Users\Shiro\AppData\Local\Temp\epetcare_u2iroxjt.sqlite3
2025-09-26 01:43:40,222 - epetcare - INFO - Syncing with remote database
2025-09-26 01:43:40,223 - epetcare - INFO - Syncing database from https://epetcare.onrender.com using API
2025-09-26 01:43:44,042 - epetcare - ERROR - All attempts to download database failed
2025-09-26 01:43:44,042 - epetcare - WARNING - Creating a new empty database as fallback
2025-09-26 01:43:44,046 - epetcare - INFO - Database synced successfully to C:\Users\Shiro\AppData\Local\Temp\epetcare_u2iroxjt.sqlite3
2025-09-26 01:44:14,055 - epetcare - INFO - Syncing with remote database
2025-09-26 01:44:14,055 - epetcare - INFO - Syncing database from https://epetcare.onrender.com using API
2025-09-26 01:44:19,102 - epetcare - ERROR - All attempts to download database failed
2025-09-26 01:44:19,103 - epetcare - WARNING - Creating a new empty database as fallback
2025-09-26 01:44:19,106 - epetcare - INFO - Database synced successfully to C:\Users\Shiro\AppData\Local\Temp\epetcare_u2iroxjt.sqlite3
2025-09-26 01:44:49,110 - epetcare - INFO - Syncing with remote database
2025-09-26 01:44:49,110 - epetcare - INFO - Syncing database from https://epetcare.onrender.com using API
2025-09-26 01:44:53,270 - epetcare - ERROR - All attempts to download database failed
2025-09-26 01:44:53,272 - epetcare - WARNING - Creating a new empty database as fallback
2025-09-26 01:44:53,275 - epetcare - INFO - Database synced successfully to C:\Users\Shiro\AppData\Local\Temp\epetcare_u2iroxjt.sqlite3
2025-09-26 01:45:23,277 - epetcare - INFO - Syncing with remote database
2025-09-26 01:45:23,277 - epetcare - INFO - Syncing database from https://epetcare.onrender.com using API
2025-09-26 01:45:28,398 - epetcare - ERROR - All attempts to download database failed
2025-09-26 01:45:28,399 - epetcare - WARNING - Creating a new empty database as fallback
2025-09-26 01:45:28,402 - epetcare - INFO - Database synced successfully to C:\Users\Shiro\AppData\Local\Temp\epetcare_u2iroxjt.sqlite3
2025-09-26 01:45:58,405 - epetcare - INFO - Syncing with remote database
2025-09-26 01:45:58,405 - epetcare - INFO - Syncing database from https://epetcare.onrender.com using API
2025-09-26 01:46:02,761 - epetcare - ERROR - All attempts to download database failed
2025-09-26 01:46:02,763 - epetcare - WARNING - Creating a new empty database as fallback
2025-09-26 01:46:02,766 - epetcare - INFO - Database synced successfully to C:\Users\Shiro\AppData\Local\Temp\epetcare_u2iroxjt.sqlite3
2025-09-26 01:46:32,770 - epetcare - INFO - Syncing with remote database
2025-09-26 01:46:32,771 - epetcare - INFO - Syncing database from https://epetcare.onrender.com using API
2025-09-26 01:46:37,669 - epetcare - ERROR - All attempts to download database failed
2025-09-26 01:46:37,669 - epetcare - WARNING - Creating a new empty database as fallback
2025-09-26 01:46:37,672 - epetcare - INFO - Database synced successfully to C:\Users\Shiro\AppData\Local\Temp\epetcare_u2iroxjt.sqlite3
2025-09-26 01:47:07,668 - epetcare - INFO - Syncing with remote database
2025-09-26 01:47:07,669 - epetcare - INFO - Syncing database from https://epetcare.onrender.com using API
2025-09-26 01:47:12,013 - epetcare - ERROR - All attempts to download database failed
2025-09-26 01:47:12,015 - epetcare - WARNING - Creating a new empty database as fallback
2025-09-26 01:47:12,018 - epetcare - INFO - Database synced successfully to C:\Users\Shiro\AppData\Local\Temp\epetcare_u2iroxjt.sqlite3
2025-09-26 01:47:42,013 - epetcare - INFO - Syncing with remote database
2025-09-26 01:47:42,014 - epetcare - INFO - Syncing database from https://epetcare.onrender.com using API
2025-09-26 01:47:45,918 - epetcare - ERROR - All attempts to download database failed
2025-09-26 01:47:45,918 - epetcare - WARNING - Creating a new empty database as fallback
2025-09-26 01:47:45,922 - epetcare - INFO - Database synced successfully to C:\Users\Shiro\AppData\Local\Temp\epetcare_u2iroxjt.sqlite3
2025-09-26 01:48:15,928 - epetcare - INFO - Syncing with remote database
2025-09-26 01:48:15,928 - epetcare - INFO - Syncing database from https://epetcare.onrender.com using API
2025-09-26 01:48:19,778 - epetcare - ERROR - All attempts to download database failed
2025-09-26 01:48:19,779 - epetcare - WARNING - Creating a new empty database as fallback
2025-09-26 01:48:19,782 - epetcare - INFO - Database synced successfully to C:\Users\Shiro\AppData\Local\Temp\epetcare_u2iroxjt.sqlite3
2025-09-26 01:48:49,779 - epetcare - INFO - Syncing with remote database
2025-09-26 01:48:49,779 - epetcare - INFO - Syncing database from https://epetcare.onrender.com using API
2025-09-26 01:48:55,358 - epetcare - ERROR - All attempts to download database failed
2025-09-26 01:48:55,361 - epetcare - WARNING - Creating a new empty database as fallback
2025-09-26 01:48:55,364 - epetcare - INFO - Database synced successfully to C:\Users\Shiro\AppData\Local\Temp\epetcare_u2iroxjt.sqlite3
2025-09-26 01:49:25,371 - epetcare - INFO - Syncing with remote database
2025-09-26 01:49:25,371 - epetcare - INFO - Syncing database from https://epetcare.onrender.com using API
2025-09-26 01:49:29,587 - epetcare - ERROR - All attempts to download database failed
2025-09-26 01:49:29,588 - epetcare - WARNING - Creating a new empty database as fallback
2025-09-26 01:49:29,591 - epetcare - INFO - Database synced successfully to C:\Users\Shiro\AppData\Local\Temp\epetcare_u2iroxjt.sqlite3
2025-09-26 01:49:59,596 - epetcare - INFO - Syncing with remote database
2025-09-26 01:49:59,596 - epetcare - INFO - Syncing database from https://epetcare.onrender.com using API
2025-09-26 01:50:03,396 - epetcare - ERROR - All attempts to download database failed
2025-09-26 01:50:03,397 - epetcare - WARNING - Creating a new empty database as fallback
2025-09-26 01:50:03,400 - epetcare - INFO - Database synced successfully to C:\Users\Shiro\AppData\Local\Temp\epetcare_u2iroxjt.sqlite3
2025-09-26 01:50:33,401 - epetcare - INFO - Syncing with remote database
2025-09-26 01:50:33,401 - epetcare - INFO - Syncing database from https://epetcare.onrender.com using API
2025-09-26 01:50:37,628 - epetcare - ERROR - All attempts to download database failed
2025-09-26 01:50:37,628 - epetcare - WARNING - Creating a new empty database as fallback
2025-09-26 01:50:37,631 - epetcare - INFO - Database synced successfully to C:\Users\Shiro\AppData\Local\Temp\epetcare_u2iroxjt.sqlite3
2025-09-26 01:51:07,634 - epetcare - INFO - Syncing with remote database
2025-09-26 01:51:07,634 - epetcare - INFO - Syncing database from https://epetcare.onrender.com using API
2025-09-26 01:51:12,514 - epetcare - ERROR - All attempts to download database failed
2025-09-26 01:51:12,516 - epetcare - WARNING - Creating a new empty database as fallback
2025-09-26 01:51:12,518 - epetcare - INFO - Database synced successfully to C:\Users\Shiro\AppData\Local\Temp\epetcare_u2iroxjt.sqlite3
2025-09-26 01:51:42,521 - epetcare - INFO - Syncing with remote database
2025-09-26 01:51:42,521 - epetcare - INFO - Syncing database from https://epetcare.onrender.com using API
2025-09-26 01:51:48,049 - epetcare - ERROR - All attempts to download database failed
2025-09-26 01:51:48,050 - epetcare - WARNING - Creating a new empty database as fallback
2025-09-26 01:51:48,054 - epetcare - INFO - Database synced successfully to C:\Users\Shiro\AppData\Local\Temp\epetcare_u2iroxjt.sqlite3
2025-09-26 01:52:18,065 - epetcare - INFO - Syncing with remote database
2025-09-26 01:52:18,065 - epetcare - INFO - Syncing database from https://epetcare.onrender.com using API
2025-09-26 01:52:21,953 - epetcare - ERROR - All attempts to download database failed
2025-09-26 01:52:21,955 - epetcare - WARNING - Creating a new empty database as fallback
2025-09-26 01:52:21,957 - epetcare - INFO - Database synced successfully to C:\Users\Shiro\AppData\Local\Temp\epetcare_u2iroxjt.sqlite3
2025-09-26 01:52:51,968 - epetcare - INFO - Syncing with remote database
2025-09-26 01:52:51,968 - epetcare - INFO - Syncing database from https://epetcare.onrender.com using API
2025-09-26 01:52:57,793 - epetcare - ERROR - All attempts to download database failed
2025-09-26 01:52:57,794 - epetcare - WARNING - Creating a new empty database as fallback
2025-09-26 01:52:57,797 - epetcare - INFO - Database synced successfully to C:\Users\Shiro\AppData\Local\Temp\epetcare_u2iroxjt.sqlite3
2025-09-26 01:53:27,803 - epetcare - INFO - Syncing with remote database
2025-09-26 01:53:27,803 - epetcare - INFO - Syncing database from https://epetcare.onrender.com using API
2025-09-26 01:53:32,159 - epetcare - ERROR - All attempts to download database failed
2025-09-26 01:53:32,165 - epetcare - WARNING - Creating a new empty database as fallback
2025-09-26 01:53:32,168 - epetcare - INFO - Database synced successfully to C:\Users\Shiro\AppData\Local\Temp\epetcare_u2iroxjt.sqlite3
2025-09-26 01:54:02,166 - epetcare - INFO - Syncing with remote database
2025-09-26 01:54:02,168 - epetcare - INFO - Syncing database from https://epetcare.onrender.com using API
2025-09-26 01:54:06,899 - epetcare - ERROR - All attempts to download database failed
2025-09-26 01:54:06,900 - epetcare - WARNING - Creating a new empty database as fallback
2025-09-26 01:54:06,903 - epetcare - INFO - Database synced successfully to C:\Users\Shiro\AppData\Local\Temp\epetcare_u2iroxjt.sqlite3
2025-09-26 01:54:36,922 - epetcare - INFO - Syncing with remote database
2025-09-26 01:54:36,922 - epetcare - INFO - Syncing database from https://epetcare.onrender.com using API
2025-09-26 01:54:41,631 - epetcare - ERROR - All attempts to download database failed
2025-09-26 01:54:41,632 - epetcare - WARNING - Creating a new empty database as fallback
2025-09-26 01:54:41,635 - epetcare - INFO - Database synced successfully to C:\Users\Shiro\AppData\Local\Temp\epetcare_u2iroxjt.sqlite3
2025-09-26 01:55:11,637 - epetcare - INFO - Syncing with remote database
2025-09-26 01:55:11,638 - epetcare - INFO - Syncing database from https://epetcare.onrender.com using API
2025-09-26 01:55:16,218 - epetcare - ERROR - All attempts to download database failed
2025-09-26 01:55:16,218 - epetcare - WARNING - Creating a new empty database as fallback
2025-09-26 01:55:16,221 - epetcare - INFO - Database synced successfully to C:\Users\Shiro\AppData\Local\Temp\epetcare_u2iroxjt.sqlite3
2025-09-26 01:55:46,222 - epetcare - INFO - Syncing with remote database
2025-09-26 01:55:46,222 - epetcare - INFO - Syncing database from https://epetcare.onrender.com using API
2025-09-26 01:55:51,534 - epetcare - ERROR - All attempts to download database failed
2025-09-26 01:55:51,536 - epetcare - WARNING - Creating a new empty database as fallback
2025-09-26 01:55:51,539 - epetcare - INFO - Database synced successfully to C:\Users\Shiro\AppData\Local\Temp\epetcare_u2iroxjt.sqlite3
2025-09-26 01:56:21,540 - epetcare - INFO - Syncing with remote database
2025-09-26 01:56:21,541 - epetcare - INFO - Syncing database from https://epetcare.onrender.com using API
2025-09-26 01:56:27,638 - epetcare - ERROR - All attempts to download database failed
2025-09-26 01:56:27,640 - epetcare - WARNING - Creating a new empty database as fallback
2025-09-26 01:56:27,643 - epetcare - INFO - Database synced successfully to C:\Users\Shiro\AppData\Local\Temp\epetcare_u2iroxjt.sqlite3
2025-09-26 01:56:57,644 - epetcare - INFO - Syncing with remote database
2025-09-26 01:56:57,645 - epetcare - INFO - Syncing database from https://epetcare.onrender.com using API
2025-09-26 01:57:01,546 - epetcare - ERROR - All attempts to download database failed
2025-09-26 01:57:01,547 - epetcare - WARNING - Creating a new empty database as fallback
2025-09-26 01:57:01,549 - epetcare - INFO - Database synced successfully to C:\Users\Shiro\AppData\Local\Temp\epetcare_u2iroxjt.sqlite3
2025-09-26 01:57:31,560 - epetcare - INFO - Syncing with remote database
2025-09-26 01:57:31,560 - epetcare - INFO - Syncing database from https://epetcare.onrender.com using API
2025-09-26 01:57:35,967 - epetcare - ERROR - All attempts to download database failed
2025-09-26 01:57:35,968 - epetcare - WARNING - Creating a new empty database as fallback
2025-09-26 01:57:35,971 - epetcare - INFO - Database synced successfully to C:\Users\Shiro\AppData\Local\Temp\epetcare_u2iroxjt.sqlite3
2025-09-26 01:58:05,982 - epetcare - INFO - Syncing with remote database
2025-09-26 01:58:05,982 - epetcare - INFO - Syncing database from https://epetcare.onrender.com using API
2025-09-26 01:58:10,907 - epetcare - ERROR - All attempts to download database failed
2025-09-26 01:58:10,908 - epetcare - WARNING - Creating a new empty database as fallback
2025-09-26 01:58:10,911 - epetcare - INFO - Database synced successfully to C:\Users\Shiro\AppData\Local\Temp\epetcare_u2iroxjt.sqlite3
2025-09-26 01:58:40,923 - epetcare - INFO - Syncing with remote database
2025-09-26 01:58:40,923 - epetcare - INFO - Syncing database from https://epetcare.onrender.com using API
2025-09-26 01:58:45,675 - epetcare - ERROR - All attempts to download database failed
2025-09-26 01:58:45,676 - epetcare - WARNING - Creating a new empty database as fallback
2025-09-26 01:58:45,681 - epetcare - INFO - Database synced successfully to C:\Users\Shiro\AppData\Local\Temp\epetcare_u2iroxjt.sqlite3
2025-09-26 01:59:15,676 - epetcare - INFO - Syncing with remote database
2025-09-26 01:59:15,677 - epetcare - INFO - Syncing database from https://epetcare.onrender.com using API
2025-09-26 01:59:19,971 - epetcare - ERROR - All attempts to download database failed
2025-09-26 01:59:19,972 - epetcare - WARNING - Creating a new empty database as fallback
2025-09-26 01:59:19,975 - epetcare - INFO - Database synced successfully to C:\Users\Shiro\AppData\Local\Temp\epetcare_u2iroxjt.sqlite3
2025-09-26 01:59:49,973 - epetcare - INFO - Syncing with remote database
2025-09-26 01:59:49,973 - epetcare - INFO - Syncing database from https://epetcare.onrender.com using API
2025-09-26 01:59:55,057 - epetcare - ERROR - All attempts to download database failed
2025-09-26 01:59:55,058 - epetcare - WARNING - Creating a new empty database as fallback
2025-09-26 01:59:55,061 - epetcare - INFO - Database synced successfully to C:\Users\Shiro\AppData\Local\Temp\epetcare_u2iroxjt.sqlite3
2025-09-26 02:00:25,068 - epetcare - INFO - Syncing with remote database
2025-09-26 02:00:25,069 - epetcare - INFO - Syncing database from https://epetcare.onrender.com using API
2025-09-26 02:00:29,324 - epetcare - ERROR - All attempts to download database failed
2025-09-26 02:00:29,324 - epetcare - WARNING - Creating a new empty database as fallback
2025-09-26 02:00:29,327 - epetcare - INFO - Database synced successfully to C:\Users\Shiro\AppData\Local\Temp\epetcare_u2iroxjt.sqlite3
2025-09-26 02:00:59,323 - epetcare - INFO - Syncing with remote database
2025-09-26 02:00:59,323 - epetcare - INFO - Syncing database from https://epetcare.onrender.com using API
2025-09-26 02:01:04,002 - epetcare - ERROR - All attempts to download database failed
2025-09-26 02:01:04,002 - epetcare - WARNING - Creating a new empty database as fallback
2025-09-26 02:01:04,005 - epetcare - INFO - Database synced successfully to C:\Users\Shiro\AppData\Local\Temp\epetcare_u2iroxjt.sqlite3
2025-09-26 02:01:33,999 - epetcare - INFO - Syncing with remote database
2025-09-26 02:01:34,000 - epetcare - INFO - Syncing database from https://epetcare.onrender.com using API
2025-09-26 02:01:37,952 - epetcare - ERROR - All attempts to download database failed
2025-09-26 02:01:37,953 - epetcare - WARNING - Creating a new empty database as fallback
2025-09-26 02:01:37,956 - epetcare - INFO - Database synced successfully to C:\Users\Shiro\AppData\Local\Temp\epetcare_u2iroxjt.sqlite3
2025-09-26 02:02:07,957 - epetcare - INFO - Syncing with remote database
2025-09-26 02:02:07,957 - epetcare - INFO - Syncing database from https://epetcare.onrender.com using API
2025-09-26 02:02:12,341 - epetcare - ERROR - All attempts to download database failed
2025-09-26 02:02:12,341 - epetcare - WARNING - Creating a new empty database as fallback
2025-09-26 02:02:12,344 - epetcare - INFO - Database synced successfully to C:\Users\Shiro\AppData\Local\Temp\epetcare_u2iroxjt.sqlite3
2025-09-26 02:02:42,341 - epetcare - INFO - Syncing with remote database
2025-09-26 02:02:42,431 - epetcare - INFO - Syncing database from https://epetcare.onrender.com using API
2025-09-26 02:02:46,670 - epetcare - ERROR - All attempts to download database failed
2025-09-26 02:02:46,670 - epetcare - WARNING - Creating a new empty database as fallback
2025-09-26 02:02:46,673 - epetcare - INFO - Database synced successfully to C:\Users\Shiro\AppData\Local\Temp\epetcare_u2iroxjt.sqlite3
2025-09-26 02:03:16,687 - epetcare - INFO - Syncing with remote database
2025-09-26 02:03:16,687 - epetcare - INFO - Syncing database from https://epetcare.onrender.com using API
2025-09-26 02:03:21,069 - epetcare - ERROR - All attempts to download database failed
2025-09-26 02:03:21,070 - epetcare - WARNING - Creating a new empty database as fallback
2025-09-26 02:03:21,072 - epetcare - INFO - Database synced successfully to C:\Users\Shiro\AppData\Local\Temp\epetcare_u2iroxjt.sqlite3
2025-09-26 02:03:51,079 - epetcare - INFO - Syncing with remote database
2025-09-26 02:03:51,080 - epetcare - INFO - Syncing database from https://epetcare.onrender.com using API
2025-09-26 02:03:55,469 - epetcare - ERROR - All attempts to download database failed
2025-09-26 02:03:55,469 - epetcare - WARNING - Creating a new empty database as fallback
2025-09-26 02:03:55,472 - epetcare - INFO - Database synced successfully to C:\Users\Shiro\AppData\Local\Temp\epetcare_u2iroxjt.sqlite3
2025-09-26 02:04:25,470 - epetcare - INFO - Syncing with remote database
2025-09-26 02:04:25,470 - epetcare - INFO - Syncing database from https://epetcare.onrender.com using API
2025-09-26 02:04:29,808 - epetcare - ERROR - All attempts to download database failed
2025-09-26 02:04:29,808 - epetcare - WARNING - Creating a new empty database as fallback
2025-09-26 02:04:29,811 - epetcare - INFO - Database synced successfully to C:\Users\Shiro\AppData\Local\Temp\epetcare_u2iroxjt.sqlite3
2025-09-26 02:04:59,810 - epetcare - INFO - Syncing with remote database
2025-09-26 02:04:59,810 - epetcare - INFO - Syncing database from https://epetcare.onrender.com using API
2025-09-26 02:05:03,718 - epetcare - ERROR - All attempts to download database failed
2025-09-26 02:05:03,719 - epetcare - WARNING - Creating a new empty database as fallback
2025-09-26 02:05:03,722 - epetcare - INFO - Database synced successfully to C:\Users\Shiro\AppData\Local\Temp\epetcare_u2iroxjt.sqlite3
2025-09-26 02:05:33,711 - epetcare - INFO - Syncing with remote database
2025-09-26 02:05:33,711 - epetcare - INFO - Syncing database from https://epetcare.onrender.com using API
2025-09-26 02:05:37,837 - epetcare - ERROR - All attempts to download database failed
2025-09-26 02:05:37,838 - epetcare - WARNING - Creating a new empty database as fallback
2025-09-26 02:05:37,841 - epetcare - INFO - Database synced successfully to C:\Users\Shiro\AppData\Local\Temp\epetcare_u2iroxjt.sqlite3
2025-09-26 02:06:07,838 - epetcare - INFO - Syncing with remote database
2025-09-26 02:06:07,839 - epetcare - INFO - Syncing database from https://epetcare.onrender.com using API
2025-09-26 02:06:12,106 - epetcare - ERROR - All attempts to download database failed
2025-09-26 02:06:12,107 - epetcare - WARNING - Creating a new empty database as fallback
2025-09-26 02:06:12,110 - epetcare - INFO - Database synced successfully to C:\Users\Shiro\AppData\Local\Temp\epetcare_u2iroxjt.sqlite3
2025-09-26 02:06:42,117 - epetcare - INFO - Syncing with remote database
2025-09-26 02:06:42,117 - epetcare - INFO - Syncing database from https://epetcare.onrender.com using API
2025-09-26 02:06:46,786 - epetcare - ERROR - All attempts to download database failed
2025-09-26 02:06:46,787 - epetcare - WARNING - Creating a new empty database as fallback
2025-09-26 02:06:46,790 - epetcare - INFO - Database synced successfully to C:\Users\Shiro\AppData\Local\Temp\epetcare_u2iroxjt.sqlite3
2025-09-26 02:07:16,794 - epetcare - INFO - Syncing with remote database
2025-09-26 02:07:16,796 - epetcare - INFO - Syncing database from https://epetcare.onrender.com using API
2025-09-26 02:07:21,115 - epetcare - ERROR - All attempts to download database failed
2025-09-26 02:07:21,228 - epetcare - WARNING - Creating a new empty database as fallback
2025-09-26 02:07:21,232 - epetcare - INFO - Database synced successfully to C:\Users\Shiro\AppData\Local\Temp\epetcare_u2iroxjt.sqlite3
2025-09-26 02:07:51,234 - epetcare - INFO - Syncing with remote database
2025-09-26 02:07:51,234 - epetcare - INFO - Syncing database from https://epetcare.onrender.com using API
2025-09-26 02:07:56,914 - epetcare - ERROR - All attempts to download database failed
2025-09-26 02:07:56,914 - epetcare - WARNING - Creating a new empty database as fallback
2025-09-26 02:07:56,917 - epetcare - INFO - Database synced successfully to C:\Users\Shiro\AppData\Local\Temp\epetcare_u2iroxjt.sqlite3
2025-09-26 02:08:26,921 - epetcare - INFO - Syncing with remote database
2025-09-26 02:08:26,921 - epetcare - INFO - Syncing database from https://epetcare.onrender.com using API
2025-09-26 02:08:31,664 - epetcare - ERROR - All attempts to download database failed
2025-09-26 02:08:31,664 - epetcare - WARNING - Creating a new empty database as fallback
2025-09-26 02:08:31,667 - epetcare - INFO - Database synced successfully to C:\Users\Shiro\AppData\Local\Temp\epetcare_u2iroxjt.sqlite3
2025-09-26 02:09:01,667 - epetcare - INFO - Syncing with remote database
2025-09-26 02:09:01,667 - epetcare - INFO - Syncing database from https://epetcare.onrender.com using API
2025-09-26 02:09:07,782 - epetcare - ERROR - All attempts to download database failed
2025-09-26 02:09:07,782 - epetcare - WARNING - Creating a new empty database as fallback
2025-09-26 02:09:07,786 - epetcare - INFO - Database synced successfully to C:\Users\Shiro\AppData\Local\Temp\epetcare_u2iroxjt.sqlite3
2025-09-26 02:09:37,793 - epetcare - INFO - Syncing with remote database
2025-09-26 02:09:37,793 - epetcare - INFO - Syncing database from https://epetcare.onrender.com using API
2025-09-26 02:09:42,152 - epetcare - ERROR - All attempts to download database failed
2025-09-26 02:09:42,153 - epetcare - WARNING - Creating a new empty database as fallback
2025-09-26 02:09:42,156 - epetcare - INFO - Database synced successfully to C:\Users\Shiro\AppData\Local\Temp\epetcare_u2iroxjt.sqlite3
